Workbook

Sheet BOLÃO - PALPITES
A1: QUINTA | B1: 0.66666667 | C1: 0.95833333 | H1: SEXTA | I1: 0.66666667 | J1: 0.91666667 | O1: SÁBADO | P1: 0.66666667 | Q1: 0.79166667 | R1: 0.91666667 | S1: 0.041666667 | V1: DOMINGO | W1: 0.58333333 | X1: 0.70833333 | Y1: 0.83333333 | Z1: 0.95833333 | AC1: SEGUNDA | AD1: 0.54166667 | AE1: 0.66666667 | AF1: 0.79166667 | AG1: 0.91666667
A2: DIA 1 - 11/06 | B2: MÉX x AFS | C2: COR x TCH | D2: TOTAL | E2: Meus palpites (Nicolas) | H2: DIA 2 - 12/6 | I2: CAN x BOS | J2: EUA x PAR | K2: TOTAL | L2: Meus palpites (Nicolas) | O2: DIA 3 - 13/06 | P2: CAT x SUI | Q2: BRA x MAR | R2: HAI x ESC | S2: AUS x TUR | T2: TOTAL | V2: DIA 4 - 14/06 | W2: ALE x CUR | X2: HOL x JAP | Y2: COM x EQU | Z2: SUE x TUN | AA2: TOTAL | AC2: DIA 5 - 15/06 | AD2: ESP x CAB | AE2: BEL x EGI | AF2: ARA x URU | AG2: IRÃ x NZL | AH2: TOTAL
A3: Alisson Garcia | B3: 3x0 | C3: 1x2 | D3: =IF(COUNTA(B3:C3)=0,"",SUM(IF(OR(B3="",B$25=""),0,IF(B3=B$25,5,IFERROR(IF(SIGN(VALUE(LEFT(B3,FIND("x",B3)-1))-VALUE(MID(B3,FIND("x",B3)+1,99)))=SIGN(VALUE(LEFT(B$25,FIND("x",B$25)-1))-VALUE(MID(B$25,FIND("x",B$25)+1,99))),IF(VALUE(LEFT(B$25,FIND("x",B$25)-1))=VALUE(MID(B$25,FIND("x",B$25)+1,99)),1,2),0),0))),IF(OR(C3="",C$25=""),0,IF(C3=C$25,5,IFERROR(IF(SIGN(VALUE(LEFT(C3,FIND("x",C3)-1))-VALUE(MID(C3,FIND("x",C3)+1,99)))=SIGN(VALUE(LEFT(C$25,FIND("x",C$25)-1))-VALUE(MID(C$25,FIND("x",C$25)+1,99))),IF(VALUE(LEFT(C$25,FIND("x",C$25)-1))=VALUE(MID(C$25,FIND("x",C$25)+1,99)),1,2),0),0))))&" ("&SUM(IF(AND(B3<>"",B3=B$25),1,0),IF(AND(C3<>"",C3=C$25),1,0))&")") -> 2 (0) | E3: 16:00 México x África do Sul | H3: Alisson Garcia | I3: 2x1 | J3: 1x1 | K3: =IF(COUNTA(I3:J3)=0,"",SUM(IF(OR(I3="",I$25=""),0,IF(I3=I$25,5,IFERROR(IF(SIGN(VALUE(LEFT(I3,FIND("x",I3)-1))-VALUE(MID(I3,FIND("x",I3)+1,99)))=SIGN(VALUE(LEFT(I$25,FIND("x",I$25)-1))-VALUE(MID(I$25,FIND("x",I$25)+1,99))),IF(VALUE(LEFT(I$25,FIND("x",I$25)-1))=VALUE(MID(I$25,FIND("x",I$25)+1,99)),1,2),0),0))),IF(OR(J3="",J$25=""),0,IF(J3=J$25,5,IFERROR(IF(SIGN(VALUE(LEFT(J3,FIND("x",J3)-1))-VALUE(MID(J3,FIND("x",J3)+1,99)))=SIGN(VALUE(LEFT(J$25,FIND("x",J$25)-1))-VALUE(MID(J$25,FIND("x",J$25)+1,99))),IF(VALUE(LEFT(J$25,FIND("x",J$25)-1))=VALUE(MID(J$25,FIND("x",J$25)+1,99)),1,2),0),0))))&" ("&SUM(IF(AND(I3<>"",I3=I$25),1,0),IF(AND(J3<>"",J3=J$25),1,0))&")") -> 0 (0) | L3: 16:00 Canadá x Bósnia | O3: Alisson Garcia | P3: 0x4 | Q3: 3x1 | R3: 1x2 | S3: 0x3 | T3: =IF(COUNTA(P3:S3)=0,"",SUM(IF(OR(P3="",P$25=""),0,IF(P3=P$25,5,IFERROR(IF(SIGN(VALUE(LEFT(P3,FIND("x",P3)-1))-VALUE(MID(P3,FIND("x",P3)+1,99)))=SIGN(VALUE(LEFT(P$25,FIND("x",P$25)-1))-VALUE(MID(P$25,FIND("x",P$25)+1,99))),IF(VALUE(LEFT(P$25,FIND("x",P$25)-1))=VALUE(MID(P$25,FIND("x",P$25)+1,99)),1,2),0),0))),IF(OR(Q3="",Q$25=""),0,IF(Q3=Q$25,5,IFERROR(IF(SIGN(VALUE(LEFT(Q3,FIND("x",Q3)-1))-VALUE(MID(Q3,FIND("x",Q3)+1,99)))=SIGN(VALUE(LEFT(Q$25,FIND("x",Q$25)-1))-VALUE(MID(Q$25,FIND("x",Q$25)+1,99))),IF(VALUE(LEFT(Q$25,FIND("x",Q$25)-1))=VALUE(MID(Q$25,FIND("x",Q$25)+1,99)),1,2),0),0))),IF(OR(R3="",R$25=""),0,IF(R3=R$25,5,IFERROR(IF(SIGN(VALUE(LEFT(R3,FIND("x",R3)-1))-VALUE(MID(R3,FIND("x",R3)+1,99)))=SIGN(VALUE(LEFT(R$25,FIND("x",R$25)-1))-VALUE(MID(R$25,FIND("x",R$25)+1,99))),IF(VALUE(LEFT(R$25,FIND("x",R$25)-1))=VALUE(MID(R$25,FIND("x",R$25)+1,99)),1,2),0),0))),IF(OR(S3="",S$25=""),0,IF(S3=S$25,5,IFERROR(IF(SIGN(VALUE(LEFT(S3,FIND("x",S3)-1))-VALUE(MID(S3,FIND("x",S3)+1,99)))=SIGN(VALUE(LEFT(S$25,FIND("x",S$25)-1))-VALUE(MID(S$25,FIND("x",S$25)+1,99))),IF(VALUE(LEFT(S$25,FIND("x",S$25)-1))=VALUE(MID(S$25,FIND("x",S$25)+1,99)),1,2),0),0))))&" ("&SUM(IF(AND(P3<>"",P3=P$25),1,0),IF(AND(Q3<>"",Q3=Q$25),1,0),IF(AND(R3<>"",R3=R$25),1,0),IF(AND(S3<>"",S3=S$25),1,0))&")") -> 2 (0) | V3: Alisson Garcia | AA3: =IF(COUNTA(W3:Z3)=0,"",SUM(IF(OR(W3="",W$25=""),0,IF(W3=W$25,5,IFERROR(IF(SIGN(VALUE(LEFT(W3,FIND("x",W3)-1))-VALUE(MID(W3,FIND("x",W3)+1,99)))=SIGN(VALUE(LEFT(W$25,FIND("x",W$25)-1))-VALUE(MID(W$25,FIND("x",W$25)+1,99))),IF(VALUE(LEFT(W$25,FIND("x",W$25)-1))=VALUE(MID(W$25,FIND("x",W$25)+1,99)),1,2),0),0))),IF(OR(X3="",X$25=""),0,IF(X3=X$25,5,IFERROR(IF(SIGN(VALUE(LEFT(X3,FIND("x",X3)-1))-VALUE(MID(X3,FIND("x",X3)+1,99)))=SIGN(VALUE(LEFT(X$25,FIND("x",X$25)-1))-VALUE(MID(X$25,FIND("x",X$25)+1,99))),IF(VALUE(LEFT(X$25,FIND("x",X$25)-1))=VALUE(MID(X$25,FIND("x",X$25)+1,99)),1,2),0),0))),IF(OR(Y3="",Y$25=""),0,IF(Y3=Y$25,5,IFERROR(IF(SIGN(VALUE(LEFT(Y3,FIND("x",Y3)-1))-VALUE(MID(Y3,FIND("x",Y3)+1,99)))=SIGN(VALUE(LEFT(Y$25,FIND("x",Y$25)-1))-VALUE(MID(Y$25,FIND("x",Y$25)+1,99))),IF(VALUE(LEFT(Y$25,FIND("x",Y$25)-1))=VALUE(MID(Y$25,FIND("x",Y$25)+1,99)),1,2),0),0))),IF(OR(Z3="",Z$25=""),0,IF(Z3=Z$25,5,IFERROR(IF(SIGN(VALUE(LEFT(Z3,FIND("x",Z3)-1))-VALUE(MID(Z3,FIND("x",Z3)+1,99)))=SIGN(VALUE(LEFT(Z$25,FIND("x",Z$25)-1))-VALUE(MID(Z$25,FIND("x",Z$25)+1,99))),IF(VALUE(LEFT(Z$25,FIND("x",Z$25)-1))=VALUE(MID(Z$25,FIND("x",Z$25)+1,99)),1,2),0),0))))&" ("&SUM(IF(AND(W3<>"",W3=W$25),1,0),IF(AND(X3<>"",X3=X$25),1,0),IF(AND(Y3<>"",Y3=Y$25),1,0),IF(AND(Z3<>"",Z3=Z$25),1,0))&")") | AC3: Brenno | AH3: =IF(COUNTA(AD3:AG3)=0,"",SUM(IF(OR(AD3="",AD$14=""),0,IF(AD3=AD$14,5,IFERROR(IF(SIGN(VALUE(LEFT(AD3,FIND("x",AD3)-1))-VALUE(MID(AD3,FIND("x",AD3)+1,99)))=SIGN(VALUE(LEFT(AD$14,FIND("x",AD$14)-1))-VALUE(MID(AD$14,FIND("x",AD$14)+1,99))),IF(VALUE(LEFT(AD$14,FIND("x",AD$14)-1))=VALUE(MID(AD$14,FIND("x",AD$14)+1,99)),1,2),0),0))),IF(OR(AE3="",AE$14=""),0,IF(AE3=AE$14,5,IFERROR(IF(SIGN(VALUE(LEFT(AE3,FIND("x",AE3)-1))-VALUE(MID(AE3,FIND("x",AE3)+1,99)))=SIGN(VALUE(LEFT(AE$14,FIND("x",AE$14)-1))-VALUE(MID(AE$14,FIND("x",AE$14)+1,99))),IF(VALUE(LEFT(AE$14,FIND("x",AE$14)-1))=VALUE(MID(AE$14,FIND("x",AE$14)+1,99)),1,2),0),0))),IF(OR(AF3="",AF$14=""),0,IF(AF3=AF$14,5,IFERROR(IF(SIGN(VALUE(LEFT(AF3,FIND("x",AF3)-1))-VALUE(MID(AF3,FIND("x",AF3)+1,99)))=SIGN(VALUE(LEFT(AF$14,FIND("x",AF$14)-1))-VALUE(MID(AF$14,FIND("x",AF$14)+1,99))),IF(VALUE(LEFT(AF$14,FIND("x",AF$14)-1))=VALUE(MID(AF$14,FIND("x",AF$14)+1,99)),1,2),0),0))),IF(OR(AG3="",AG$14=""),0,IF(AG3=AG$14,5,IFERROR(IF(SIGN(VALUE(LEFT(AG3,FIND("x",AG3)-1))-VALUE(MID(AG3,FIND("x",AG3)+1,99)))=SIGN(VALUE(LEFT(AG$14,FIND("x",AG$14)-1))-VALUE(MID(AG$14,FIND("x",AG$14)+1,99))),IF(VALUE(LEFT(AG$14,FIND("x",AG$14)-1))=VALUE(MID(AG$14,FIND("x",AG$14)+1,99)),1,2),0),0))))&" ("&SUM(IF(AND(AD3<>"",AD3=AD$14),1,0),IF(AND(AE3<>"",AE3=AE$14),1,0),IF(AND(AF3<>"",AF3=AF$14),1,0),IF(AND(AG3<>"",AG3=AG$14),1,0))&")")
A4: Bianca Leite | B4: 2x1 | C4: 1x0 | D4: =IF(COUNTA(B4:C4)=0,"",SUM(IF(OR(B4="",B$25=""),0,IF(B4=B$25,5,IFERROR(IF(SIGN(VALUE(LEFT(B4,FIND("x",B4)-1))-VALUE(MID(B4,FIND("x",B4)+1,99)))=SIGN(VALUE(LEFT(B$25,FIND("x",B$25)-1))-VALUE(MID(B$25,FIND("x",B$25)+1,99))),IF(VALUE(LEFT(B$25,FIND("x",B$25)-1))=VALUE(MID(B$25,FIND("x",B$25)+1,99)),1,2),0),0))),IF(OR(C4="",C$25=""),0,IF(C4=C$25,5,IFERROR(IF(SIGN(VALUE(LEFT(C4,FIND("x",C4)-1))-VALUE(MID(C4,FIND("x",C4)+1,99)))=SIGN(VALUE(LEFT(C$25,FIND("x",C$25)-1))-VALUE(MID(C$25,FIND("x",C$25)+1,99))),IF(VALUE(LEFT(C$25,FIND("x",C$25)-1))=VALUE(MID(C$25,FIND("x",C$25)+1,99)),1,2),0),0))))&" ("&SUM(IF(AND(B4<>"",B4=B$25),1,0),IF(AND(C4<>"",C4=C$25),1,0))&")") -> 4 (0) | E4: 23:00 Coréia do Sul x Tchéquia | H4: Bianca Leite | I4: 1x0 | J4: 1x2 | K4: =IF(COUNTA(I4:J4)=0,"",SUM(IF(OR(I4="",I$25=""),0,IF(I4=I$25,5,IFERROR(IF(SIGN(VALUE(LEFT(I4,FIND("x",I4)-1))-VALUE(MID(I4,FIND("x",I4)+1,99)))=SIGN(VALUE(LEFT(I$25,FIND("x",I$25)-1))-VALUE(MID(I$25,FIND("x",I$25)+1,99))),IF(VALUE(LEFT(I$25,FIND("x",I$25)-1))=VALUE(MID(I$25,FIND("x",I$25)+1,99)),1,2),0),0))),IF(OR(J4="",J$25=""),0,IF(J4=J$25,5,IFERROR(IF(SIGN(VALUE(LEFT(J4,FIND("x",J4)-1))-VALUE(MID(J4,FIND("x",J4)+1,99)))=SIGN(VALUE(LEFT(J$25,FIND("x",J$25)-1))-VALUE(MID(J$25,FIND("x",J$25)+1,99))),IF(VALUE(LEFT(J$25,FIND("x",J$25)-1))=VALUE(MID(J$25,FIND("x",J$25)+1,99)),1,2),0),0))))&" ("&SUM(IF(AND(I4<>"",I4=I$25),1,0),IF(AND(J4<>"",J4=J$25),1,0))&")") -> 0 (0) | L4: 22:00 Estados Unidos x Paraguai | O4: Bianca Leite | P4: 0x3 | Q4: 3x2 | R4: 1x3 | S4: 2x1 | T4: =IF(COUNTA(P4:S4)=0,"",SUM(IF(OR(P4="",P$25=""),0,IF(P4=P$25,5,IFERROR(IF(SIGN(VALUE(LEFT(P4,FIND("x",P4)-1))-VALUE(MID(P4,FIND("x",P4)+1,99)))=SIGN(VALUE(LEFT(P$25,FIND("x",P$25)-1))-VALUE(MID(P$25,FIND("x",P$25)+1,99))),IF(VALUE(LEFT(P$25,FIND("x",P$25)-1))=VALUE(MID(P$25,FIND("x",P$25)+1,99)),1,2),0),0))),IF(OR(Q4="",Q$25=""),0,IF(Q4=Q$25,5,IFERROR(IF(SIGN(VALUE(LEFT(Q4,FIND("x",Q4)-1))-VALUE(MID(Q4,FIND("x",Q4)+1,99)))=SIGN(VALUE(LEFT(Q$25,FIND("x",Q$25)-1))-VALUE(MID(Q$25,FIND("x",Q$25)+1,99))),IF(VALUE(LEFT(Q$25,FIND("x",Q$25)-1))=VALUE(MID(Q$25,FIND("x",Q$25)+1,99)),1,2),0),0))),IF(OR(R4="",R$25=""),0,IF(R4=R$25,5,IFERROR(IF(SIGN(VALUE(LEFT(R4,FIND("x",R4)-1))-VALUE(MID(R4,FIND("x",R4)+1,99)))=SIGN(VALUE(LEFT(R$25,FIND("x",R$25)-1))-VALUE(MID(R$25,FIND("x",R$25)+1,99))),IF(VALUE(LEFT(R$25,FIND("x",R$25)-1))=VALUE(MID(R$25,FIND("x",R$25)+1,99)),1,2),0),0))),IF(OR(S4="",S$25=""),0,IF(S4=S$25,5,IFERROR(IF(SIGN(VALUE(LEFT(S4,FIND("x",S4)-1))-VALUE(MID(S4,FIND("x",S4)+1,99)))=SIGN(VALUE(LEFT(S$25,FIND("x",S$25)-1))-VALUE(MID(S$25,FIND("x",S$25)+1,99))),IF(VALUE(LEFT(S$25,FIND("x",S$25)-1))=VALUE(MID(S$25,FIND("x",S$25)+1,99)),1,2),0),0))))&" ("&SUM(IF(AND(P4<>"",P4=P$25),1,0),IF(AND(Q4<>"",Q4=Q$25),1,0),IF(AND(R4<>"",R4=R$25),1,0),IF(AND(S4<>"",S4=S$25),1,0))&")") -> 4 (0) | V4: Bianca Leite | AA4: =IF(COUNTA(W4:Z4)=0,"",SUM(IF(OR(W4="",W$25=""),0,IF(W4=W$25,5,IFERROR(IF(SIGN(VALUE(LEFT(W4,FIND("x",W4)-1))-VALUE(MID(W4,FIND("x",W4)+1,99)))=SIGN(VALUE(LEFT(W$25,FIND("x",W$25)-1))-VALUE(MID(W$25,FIND("x",W$25)+1,99))),IF(VALUE(LEFT(W$25,FIND("x",W$25)-1))=VALUE(MID(W$25,FIND("x",W$25)+1,99)),1,2),0),0))),IF(OR(X4="",X$25=""),0,IF(X4=X$25,5,IFERROR(IF(SIGN(VALUE(LEFT(X4,FIND("x",X4)-1))-VALUE(MID(X4,FIND("x",X4)+1,99)))=SIGN(VALUE(LEFT(X$25,FIND("x",X$25)-1))-VALUE(MID(X$25,FIND("x",X$25)+1,99))),IF(VALUE(LEFT(X$25,FIND("x",X$25)-1))=VALUE(MID(X$25,FIND("x",X$25)+1,99)),1,2),0),0))),IF(OR(Y4="",Y$25=""),0,IF(Y4=Y$25,5,IFERROR(IF(SIGN(VALUE(LEFT(Y4,FIND("x",Y4)-1))-VALUE(MID(Y4,FIND("x",Y4)+1,99)))=SIGN(VALUE(LEFT(Y$25,FIND("x",Y$25)-1))-VALUE(MID(Y$25,FIND("x",Y$25)+1,99))),IF(VALUE(LEFT(Y$25,FIND("x",Y$25)-1))=VALUE(MID(Y$25,FIND("x",Y$25)+1,99)),1,2),0),0))),IF(OR(Z4="",Z$25=""),0,IF(Z4=Z$25,5,IFERROR(IF(SIGN(VALUE(LEFT(Z4,FIND("x",Z4)-1))-VALUE(MID(Z4,FIND("x",Z4)+1,99)))=SIGN(VALUE(LEFT(Z$25,FIND("x",Z$25)-1))-VALUE(MID(Z$25,FIND("x",Z$25)+1,99))),IF(VALUE(LEFT(Z$25,FIND("x",Z$25)-1))=VALUE(MID(Z$25,FIND("x",Z$25)+1,99)),1,2),0),0))))&" ("&SUM(IF(AND(W4<>"",W4=W$25),1,0),IF(AND(X4<>"",X4=X$25),1,0),IF(AND(Y4<>"",Y4=Y$25),1,0),IF(AND(Z4<>"",Z4=Z$25),1,0))&")") | AC4: Bernardo | AH4: =IF(COUNTA(AD4:AG4)=0,"",SUM(IF(OR(AD4="",AD$14=""),0,IF(AD4=AD$14,5,IFERROR(IF(SIGN(VALUE(LEFT(AD4,FIND("x",AD4)-1))-VALUE(MID(AD4,FIND("x",AD4)+1,99)))=SIGN(VALUE(LEFT(AD$14,FIND("x",AD$14)-1))-VALUE(MID(AD$14,FIND("x",AD$14)+1,99))),IF(VALUE(LEFT(AD$14,FIND("x",AD$14)-1))=VALUE(MID(AD$14,FIND("x",AD$14)+1,99)),1,2),0),0))),IF(OR(AE4="",AE$14=""),0,IF(AE4=AE$14,5,IFERROR(IF(SIGN(VALUE(LEFT(AE4,FIND("x",AE4)-1))-VALUE(MID(AE4,FIND("x",AE4)+1,99)))=SIGN(VALUE(LEFT(AE$14,FIND("x",AE$14)-1))-VALUE(MID(AE$14,FIND("x",AE$14)+1,99))),IF(VALUE(LEFT(AE$14,FIND("x",AE$14)-1))=VALUE(MID(AE$14,FIND("x",AE$14)+1,99)),1,2),0),0))),IF(OR(AF4="",AF$14=""),0,IF(AF4=AF$14,5,IFERROR(IF(SIGN(VALUE(LEFT(AF4,FIND("x",AF4)-1))-VALUE(MID(AF4,FIND("x",AF4)+1,99)))=SIGN(VALUE(LEFT(AF$14,FIND("x",AF$14)-1))-VALUE(MID(AF$14,FIND("x",AF$14)+1,99))),IF(VALUE(LEFT(AF$14,FIND("x",AF$14)-1))=VALUE(MID(AF$14,FIND("x",AF$14)+1,99)),1,2),0),0))),IF(OR(AG4="",AG$14=""),0,IF(AG4=AG$14,5,IFERROR(IF(SIGN(VALUE(LEFT(AG4,FIND("x",AG4)-1))-VALUE(MID(AG4,FIND("x",AG4)+1,99)))=SIGN(VALUE(LEFT(AG$14,FIND("x",AG$14)-1))-VALUE(MID(AG$14,FIND("x",AG$14)+1,99))),IF(VALUE(LEFT(AG$14,FIND("x",AG$14)-1))=VALUE(MID(AG$14,FIND("x",AG$14)+1,99)),1,2),0),0))))&" ("&SUM(IF(AND(AD4<>"",AD4=AD$14),1,0),IF(AND(AE4<>"",AE4=AE$14),1,0),IF(AND(AF4<>"",AF4=AF$14),1,0),IF(AND(AG4<>"",AG4=AG$14),1,0))&")")
A5: Bernardo | B5: 1x1 | C5: 2x1 | D5: =IF(COUNTA(B5:C5)=0,"",SUM(IF(OR(B5="",B$25=""),0,IF(B5=B$25,5,IFERROR(IF(SIGN(VALUE(LEFT(B5,FIND("x",B5)-1))-VALUE(MID(B5,FIND("x",B5)+1,99)))=SIGN(VALUE(LEFT(B$25,FIND("x",B$25)-1))-VALUE(MID(B$25,FIND("x",B$25)+1,99))),IF(VALUE(LEFT(B$25,FIND("x",B$25)-1))=VALUE(MID(B$25,FIND("x",B$25)+1,99)),1,2),0),0))),IF(OR(C5="",C$25=""),0,IF(C5=C$25,5,IFERROR(IF(SIGN(VALUE(LEFT(C5,FIND("x",C5)-1))-VALUE(MID(C5,FIND("x",C5)+1,99)))=SIGN(VALUE(LEFT(C$25,FIND("x",C$25)-1))-VALUE(MID(C$25,FIND("x",C$25)+1,99))),IF(VALUE(LEFT(C$25,FIND("x",C$25)-1))=VALUE(MID(C$25,FIND("x",C$25)+1,99)),1,2),0),0))))&" ("&SUM(IF(AND(B5<>"",B5=B$25),1,0),IF(AND(C5<>"",C5=C$25),1,0))&")") -> 5 (1) | H5: Bernardo | I5: 0x1 | J5: 1x2 | K5: =IF(COUNTA(I5:J5)=0,"",SUM(IF(OR(I5="",I$25=""),0,IF(I5=I$25,5,IFERROR(IF(SIGN(VALUE(LEFT(I5,FIND("x",I5)-1))-VALUE(MID(I5,FIND("x",I5)+1,99)))=SIGN(VALUE(LEFT(I$25,FIND("x",I$25)-1))-VALUE(MID(I$25,FIND("x",I$25)+1,99))),IF(VALUE(LEFT(I$25,FIND("x",I$25)-1))=VALUE(MID(I$25,FIND("x",I$25)+1,99)),1,2),0),0))),IF(OR(J5="",J$25=""),0,IF(J5=J$25,5,IFERROR(IF(SIGN(VALUE(LEFT(J5,FIND("x",J5)-1))-VALUE(MID(J5,FIND("x",J5)+1,99)))=SIGN(VALUE(LEFT(J$25,FIND("x",J$25)-1))-VALUE(MID(J$25,FIND("x",J$25)+1,99))),IF(VALUE(LEFT(J$25,FIND("x",J$25)-1))=VALUE(MID(J$25,FIND("x",J$25)+1,99)),1,2),0),0))))&" ("&SUM(IF(AND(I5<>"",I5=I$25),1,0),IF(AND(J5<>"",J5=J$25),1,0))&")") -> 0 (0) | O5: Bernardo | P5: 0x1 | Q5: 2x1 | R5: 0x2 | S5: 1x2 | T5: =IF(COUNTA(P5:S5)=0,"",SUM(IF(OR(P5="",P$25=""),0,IF(P5=P$25,5,IFERROR(IF(SIGN(VALUE(LEFT(P5,FIND("x",P5)-1))-VALUE(MID(P5,FIND("x",P5)+1,99)))=SIGN(VALUE(LEFT(P$25,FIND("x",P$25)-1))-VALUE(MID(P$25,FIND("x",P$25)+1,99))),IF(VALUE(LEFT(P$25,FIND("x",P$25)-1))=VALUE(MID(P$25,FIND("x",P$25)+1,99)),1,2),0),0))),IF(OR(Q5="",Q$25=""),0,IF(Q5=Q$25,5,IFERROR(IF(SIGN(VALUE(LEFT(Q5,FIND("x",Q5)-1))-VALUE(MID(Q5,FIND("x",Q5)+1,99)))=SIGN(VALUE(LEFT(Q$25,FIND("x",Q$25)-1))-VALUE(MID(Q$25,FIND("x",Q$25)+1,99))),IF(VALUE(LEFT(Q$25,FIND("x",Q$25)-1))=VALUE(MID(Q$25,FIND("x",Q$25)+1,99)),1,2),0),0))),IF(OR(R5="",R$25=""),0,IF(R5=R$25,5,IFERROR(IF(SIGN(VALUE(LEFT(R5,FIND("x",R5)-1))-VALUE(MID(R5,FIND("x",R5)+1,99)))=SIGN(VALUE(LEFT(R$25,FIND("x",R$25)-1))-VALUE(MID(R$25,FIND("x",R$25)+1,99))),IF(VALUE(LEFT(R$25,FIND("x",R$25)-1))=VALUE(MID(R$25,FIND("x",R$25)+1,99)),1,2),0),0))),IF(OR(S5="",S$25=""),0,IF(S5=S$25,5,IFERROR(IF(SIGN(VALUE(LEFT(S5,FIND("x",S5)-1))-VALUE(MID(S5,FIND("x",S5)+1,99)))=SIGN(VALUE(LEFT(S$25,FIND("x",S$25)-1))-VALUE(MID(S$25,FIND("x",S$25)+1,99))),IF(VALUE(LEFT(S$25,FIND("x",S$25)-1))=VALUE(MID(S$25,FIND("x",S$25)+1,99)),1,2),0),0))))&" ("&SUM(IF(AND(P5<>"",P5=P$25),1,0),IF(AND(Q5<>"",Q5=Q$25),1,0),IF(AND(R5<>"",R5=R$25),1,0),IF(AND(S5<>"",S5=S$25),1,0))&")") -> 2 (0) | V5: Bernardo | AA5: =IF(COUNTA(W5:Z5)=0,"",SUM(IF(OR(W5="",W$25=""),0,IF(W5=W$25,5,IFERROR(IF(SIGN(VALUE(LEFT(W5,FIND("x",W5)-1))-VALUE(MID(W5,FIND("x",W5)+1,99)))=SIGN(VALUE(LEFT(W$25,FIND("x",W$25)-1))-VALUE(MID(W$25,FIND("x",W$25)+1,99))),IF(VALUE(LEFT(W$25,FIND("x",W$25)-1))=VALUE(MID(W$25,FIND("x",W$25)+1,99)),1,2),0),0))),IF(OR(X5="",X$25=""),0,IF(X5=X$25,5,IFERROR(IF(SIGN(VALUE(LEFT(X5,FIND("x",X5)-1))-VALUE(MID(X5,FIND("x",X5)+1,99)))=SIGN(VALUE(LEFT(X$25,FIND("x",X$25)-1))-VALUE(MID(X$25,FIND("x",X$25)+1,99))),IF(VALUE(LEFT(X$25,FIND("x",X$25)-1))=VALUE(MID(X$25,FIND("x",X$25)+1,99)),1,2),0),0))),IF(OR(Y5="",Y$25=""),0,IF(Y5=Y$25,5,IFERROR(IF(SIGN(VALUE(LEFT(Y5,FIND("x",Y5)-1))-VALUE(MID(Y5,FIND("x",Y5)+1,99)))=SIGN(VALUE(LEFT(Y$25,FIND("x",Y$25)-1))-VALUE(MID(Y$25,FIND("x",Y$25)+1,99))),IF(VALUE(LEFT(Y$25,FIND("x",Y$25)-1))=VALUE(MID(Y$25,FIND("x",Y$25)+1,99)),1,2),0),0))),IF(OR(Z5="",Z$25=""),0,IF(Z5=Z$25,5,IFERROR(IF(SIGN(VALUE(LEFT(Z5,FIND("x",Z5)-1))-VALUE(MID(Z5,FIND("x",Z5)+1,99)))=SIGN(VALUE(LEFT(Z$25,FIND("x",Z$25)-1))-VALUE(MID(Z$25,FIND("x",Z$25)+1,99))),IF(VALUE(LEFT(Z$25,FIND("x",Z$25)-1))=VALUE(MID(Z$25,FIND("x",Z$25)+1,99)),1,2),0),0))))&" ("&SUM(IF(AND(W5<>"",W5=W$25),1,0),IF(AND(X5<>"",X5=X$25),1,0),IF(AND(Y5<>"",Y5=Y$25),1,0),IF(AND(Z5<>"",Z5=Z$25),1,0))&")") | AC5: Caio Borges | AH5: =IF(COUNTA(AD5:AG5)=0,"",SUM(IF(OR(AD5="",AD$14=""),0,IF(AD5=AD$14,5,IFERROR(IF(SIGN(VALUE(LEFT(AD5,FIND("x",AD5)-1))-VALUE(MID(AD5,FIND("x",AD5)+1,99)))=SIGN(VALUE(LEFT(AD$14,FIND("x",AD$14)-1))-VALUE(MID(AD$14,FIND("x",AD$14)+1,99))),IF(VALUE(LEFT(AD$14,FIND("x",AD$14)-1))=VALUE(MID(AD$14,FIND("x",AD$14)+1,99)),1,2),0),0))),IF(OR(AE5="",AE$14=""),0,IF(AE5=AE$14,5,IFERROR(IF(SIGN(VALUE(LEFT(AE5,FIND("x",AE5)-1))-VALUE(MID(AE5,FIND("x",AE5)+1,99)))=SIGN(VALUE(LEFT(AE$14,FIND("x",AE$14)-1))-VALUE(MID(AE$14,FIND("x",AE$14)+1,99))),IF(VALUE(LEFT(AE$14,FIND("x",AE$14)-1))=VALUE(MID(AE$14,FIND("x",AE$14)+1,99)),1,2),0),0))),IF(OR(AF5="",AF$14=""),0,IF(AF5=AF$14,5,IFERROR(IF(SIGN(VALUE(LEFT(AF5,FIND("x",AF5)-1))-VALUE(MID(AF5,FIND("x",AF5)+1,99)))=SIGN(VALUE(LEFT(AF$14,FIND("x",AF$14)-1))-VALUE(MID(AF$14,FIND("x",AF$14)+1,99))),IF(VALUE(LEFT(AF$14,FIND("x",AF$14)-1))=VALUE(MID(AF$14,FIND("x",AF$14)+1,99)),1,2),0),0))),IF(OR(AG5="",AG$14=""),0,IF(AG5=AG$14,5,IFERROR(IF(SIGN(VALUE(LEFT(AG5,FIND("x",AG5)-1))-VALUE(MID(AG5,FIND("x",AG5)+1,99)))=SIGN(VALUE(LEFT(AG$14,FIND("x",AG$14)-1))-VALUE(MID(AG$14,FIND("x",AG$14)+1,99))),IF(VALUE(LEFT(AG$14,FIND("x",AG$14)-1))=VALUE(MID(AG$14,FIND("x",AG$14)+1,99)),1,2),0),0))))&" ("&SUM(IF(AND(AD5<>"",AD5=AD$14),1,0),IF(AND(AE5<>"",AE5=AE$14),1,0),IF(AND(AF5<>"",AF5=AF$14),1,0),IF(AND(AG5<>"",AG5=AG$14),1,0))&")")
A6: Brenno Vergara | B6: 2x1 | C6: 2x2 | D6: =IF(COUNTA(B6:C6)=0,"",SUM(IF(OR(B6="",B$25=""),0,IF(B6=B$25,5,IFERROR(IF(SIGN(VALUE(LEFT(B6,FIND("x",B6)-1))-VALUE(MID(B6,FIND("x",B6)+1,99)))=SIGN(VALUE(LEFT(B$25,FIND("x",B$25)-1))-VALUE(MID(B$25,FIND("x",B$25)+1,99))),IF(VALUE(LEFT(B$25,FIND("x",B$25)-1))=VALUE(MID(B$25,FIND("x",B$25)+1,99)),1,2),0),0))),IF(OR(C6="",C$25=""),0,IF(C6=C$25,5,IFERROR(IF(SIGN(VALUE(LEFT(C6,FIND("x",C6)-1))-VALUE(MID(C6,FIND("x",C6)+1,99)))=SIGN(VALUE(LEFT(C$25,FIND("x",C$25)-1))-VALUE(MID(C$25,FIND("x",C$25)+1,99))),IF(VALUE(LEFT(C$25,FIND("x",C$25)-1))=VALUE(MID(C$25,FIND("x",C$25)+1,99)),1,2),0),0))))&" ("&SUM(IF(AND(B6<>"",B6=B$25),1,0),IF(AND(C6<>"",C6=C$25),1,0))&")") -> 2 (0) | H6: Brenno Vergara | I6: 1x2 | J6: 0x2 | K6: =IF(COUNTA(I6:J6)=0,"",SUM(IF(OR(I6="",I$25=""),0,IF(I6=I$25,5,IFERROR(IF(SIGN(VALUE(LEFT(I6,FIND("x",I6)-1))-VALUE(MID(I6,FIND("x",I6)+1,99)))=SIGN(VALUE(LEFT(I$25,FIND("x",I$25)-1))-VALUE(MID(I$25,FIND("x",I$25)+1,99))),IF(VALUE(LEFT(I$25,FIND("x",I$25)-1))=VALUE(MID(I$25,FIND("x",I$25)+1,99)),1,2),0),0))),IF(OR(J6="",J$25=""),0,IF(J6=J$25,5,IFERROR(IF(SIGN(VALUE(LEFT(J6,FIND("x",J6)-1))-VALUE(MID(J6,FIND("x",J6)+1,99)))=SIGN(VALUE(LEFT(J$25,FIND("x",J$25)-1))-VALUE(MID(J$25,FIND("x",J$25)+1,99))),IF(VALUE(LEFT(J$25,FIND("x",J$25)-1))=VALUE(MID(J$25,FIND("x",J$25)+1,99)),1,2),0),0))))&" ("&SUM(IF(AND(I6<>"",I6=I$25),1,0),IF(AND(J6<>"",J6=J$25),1,0))&")") -> 0 (0) | M6: Meus palpites (Nicolas) | O6: Brenno Vergara | P6: 0x3 | Q6: 2x1 | R6: 0x3 | S6: 0x1 | T6: =IF(COUNTA(P6:S6)=0,"",SUM(IF(OR(P6="",P$25=""),0,IF(P6=P$25,5,IFERROR(IF(SIGN(VALUE(LEFT(P6,FIND("x",P6)-1))-VALUE(MID(P6,FIND("x",P6)+1,99)))=SIGN(VALUE(LEFT(P$25,FIND("x",P$25)-1))-VALUE(MID(P$25,FIND("x",P$25)+1,99))),IF(VALUE(LEFT(P$25,FIND("x",P$25)-1))=VALUE(MID(P$25,FIND("x",P$25)+1,99)),1,2),0),0))),IF(OR(Q6="",Q$25=""),0,IF(Q6=Q$25,5,IFERROR(IF(SIGN(VALUE(LEFT(Q6,FIND("x",Q6)-1))-VALUE(MID(Q6,FIND("x",Q6)+1,99)))=SIGN(VALUE(LEFT(Q$25,FIND("x",Q$25)-1))-VALUE(MID(Q$25,FIND("x",Q$25)+1,99))),IF(VALUE(LEFT(Q$25,FIND("x",Q$25)-1))=VALUE(MID(Q$25,FIND("x",Q$25)+1,99)),1,2),0),0))),IF(OR(R6="",R$25=""),0,IF(R6=R$25,5,IFERROR(IF(SIGN(VALUE(LEFT(R6,FIND("x",R6)-1))-VALUE(MID(R6,FIND("x",R6)+1,99)))=SIGN(VALUE(LEFT(R$25,FIND("x",R$25)-1))-VALUE(MID(R$25,FIND("x",R$25)+1,99))),IF(VALUE(LEFT(R$25,FIND("x",R$25)-1))=VALUE(MID(R$25,FIND("x",R$25)+1,99)),1,2),0),0))),IF(OR(S6="",S$25=""),0,IF(S6=S$25,5,IFERROR(IF(SIGN(VALUE(LEFT(S6,FIND("x",S6)-1))-VALUE(MID(S6,FIND("x",S6)+1,99)))=SIGN(VALUE(LEFT(S$25,FIND("x",S$25)-1))-VALUE(MID(S$25,FIND("x",S$25)+1,99))),IF(VALUE(LEFT(S$25,FIND("x",S$25)-1))=VALUE(MID(S$25,FIND("x",S$25)+1,99)),1,2),0),0))))&" ("&SUM(IF(AND(P6<>"",P6=P$25),1,0),IF(AND(Q6<>"",Q6=Q$25),1,0),IF(AND(R6<>"",R6=R$25),1,0),IF(AND(S6<>"",S6=S$25),1,0))&")") -> 2 (0) | V6: Brenno Vergara | AA6: =IF(COUNTA(W6:Z6)=0,"",SUM(IF(OR(W6="",W$25=""),0,IF(W6=W$25,5,IFERROR(IF(SIGN(VALUE(LEFT(W6,FIND("x",W6)-1))-VALUE(MID(W6,FIND("x",W6)+1,99)))=SIGN(VALUE(LEFT(W$25,FIND("x",W$25)-1))-VALUE(MID(W$25,FIND("x",W$25)+1,99))),IF(VALUE(LEFT(W$25,FIND("x",W$25)-1))=VALUE(MID(W$25,FIND("x",W$25)+1,99)),1,2),0),0))),IF(OR(X6="",X$25=""),0,IF(X6=X$25,5,IFERROR(IF(SIGN(VALUE(LEFT(X6,FIND("x",X6)-1))-VALUE(MID(X6,FIND("x",X6)+1,99)))=SIGN(VALUE(LEFT(X$25,FIND("x",X$25)-1))-VALUE(MID(X$25,FIND("x",X$25)+1,99))),IF(VALUE(LEFT(X$25,FIND("x",X$25)-1))=VALUE(MID(X$25,FIND("x",X$25)+1,99)),1,2),0),0))),IF(OR(Y6="",Y$25=""),0,IF(Y6=Y$25,5,IFERROR(IF(SIGN(VALUE(LEFT(Y6,FIND("x",Y6)-1))-VALUE(MID(Y6,FIND("x",Y6)+1,99)))=SIGN(VALUE(LEFT(Y$25,FIND("x",Y$25)-1))-VALUE(MID(Y$25,FIND("x",Y$25)+1,99))),IF(VALUE(LEFT(Y$25,FIND("x",Y$25)-1))=VALUE(MID(Y$25,FIND("x",Y$25)+1,99)),1,2),0),0))),IF(OR(Z6="",Z$25=""),0,IF(Z6=Z$25,5,IFERROR(IF(SIGN(VALUE(LEFT(Z6,FIND("x",Z6)-1))-VALUE(MID(Z6,FIND("x",Z6)+1,99)))=SIGN(VALUE(LEFT(Z$25,FIND("x",Z$25)-1))-VALUE(MID(Z$25,FIND("x",Z$25)+1,99))),IF(VALUE(LEFT(Z$25,FIND("x",Z$25)-1))=VALUE(MID(Z$25,FIND("x",Z$25)+1,99)),1,2),0),0))))&" ("&SUM(IF(AND(W6<>"",W6=W$25),1,0),IF(AND(X6<>"",X6=X$25),1,0),IF(AND(Y6<>"",Y6=Y$25),1,0),IF(AND(Z6<>"",Z6=Z$25),1,0))&")") | AC6: Gabriel Mendes | AH6: =IF(COUNTA(AD6:AG6)=0,"",SUM(IF(OR(AD6="",AD$14=""),0,IF(AD6=AD$14,5,IFERROR(IF(SIGN(VALUE(LEFT(AD6,FIND("x",AD6)-1))-VALUE(MID(AD6,FIND("x",AD6)+1,99)))=SIGN(VALUE(LEFT(AD$14,FIND("x",AD$14)-1))-VALUE(MID(AD$14,FIND("x",AD$14)+1,99))),IF(VALUE(LEFT(AD$14,FIND("x",AD$14)-1))=VALUE(MID(AD$14,FIND("x",AD$14)+1,99)),1,2),0),0))),IF(OR(AE6="",AE$14=""),0,IF(AE6=AE$14,5,IFERROR(IF(SIGN(VALUE(LEFT(AE6,FIND("x",AE6)-1))-VALUE(MID(AE6,FIND("x",AE6)+1,99)))=SIGN(VALUE(LEFT(AE$14,FIND("x",AE$14)-1))-VALUE(MID(AE$14,FIND("x",AE$14)+1,99))),IF(VALUE(LEFT(AE$14,FIND("x",AE$14)-1))=VALUE(MID(AE$14,FIND("x",AE$14)+1,99)),1,2),0),0))),IF(OR(AF6="",AF$14=""),0,IF(AF6=AF$14,5,IFERROR(IF(SIGN(VALUE(LEFT(AF6,FIND("x",AF6)-1))-VALUE(MID(AF6,FIND("x",AF6)+1,99)))=SIGN(VALUE(LEFT(AF$14,FIND("x",AF$14)-1))-VALUE(MID(AF$14,FIND("x",AF$14)+1,99))),IF(VALUE(LEFT(AF$14,FIND("x",AF$14)-1))=VALUE(MID(AF$14,FIND("x",AF$14)+1,99)),1,2),0),0))),IF(OR(AG6="",AG$14=""),0,IF(AG6=AG$14,5,IFERROR(IF(SIGN(VALUE(LEFT(AG6,FIND("x",AG6)-1))-VALUE(MID(AG6,FIND("x",AG6)+1,99)))=SIGN(VALUE(LEFT(AG$14,FIND("x",AG$14)-1))-VALUE(MID(AG$14,FIND("x",AG$14)+1,99))),IF(VALUE(LEFT(AG$14,FIND("x",AG$14)-1))=VALUE(MID(AG$14,FIND("x",AG$14)+1,99)),1,2),0),0))))&" ("&SUM(IF(AND(AD6<>"",AD6=AD$14),1,0),IF(AND(AE6<>"",AE6=AE$14),1,0),IF(AND(AF6<>"",AF6=AF$14),1,0),IF(AND(AG6<>"",AG6=AG$14),1,0))&")")
A7: Caio Borges | B7: 2x1 | C7: 2x1 | D7: =IF(COUNTA(B7:C7)=0,"",SUM(IF(OR(B7="",B$25=""),0,IF(B7=B$25,5,IFERROR(IF(SIGN(VALUE(LEFT(B7,FIND("x",B7)-1))-VALUE(MID(B7,FIND("x",B7)+1,99)))=SIGN(VALUE(LEFT(B$25,FIND("x",B$25)-1))-VALUE(MID(B$25,FIND("x",B$25)+1,99))),IF(VALUE(LEFT(B$25,FIND("x",B$25)-1))=VALUE(MID(B$25,FIND("x",B$25)+1,99)),1,2),0),0))),IF(OR(C7="",C$25=""),0,IF(C7=C$25,5,IFERROR(IF(SIGN(VALUE(LEFT(C7,FIND("x",C7)-1))-VALUE(MID(C7,FIND("x",C7)+1,99)))=SIGN(VALUE(LEFT(C$25,FIND("x",C$25)-1))-VALUE(MID(C$25,FIND("x",C$25)+1,99))),IF(VALUE(LEFT(C$25,FIND("x",C$25)-1))=VALUE(MID(C$25,FIND("x",C$25)+1,99)),1,2),0),0))))&" ("&SUM(IF(AND(B7<>"",B7=B$25),1,0),IF(AND(C7<>"",C7=C$25),1,0))&")") -> 7 (1) | H7: Caio Borges | I7: 2x0 | J7: 2x1 | K7: =IF(COUNTA(I7:J7)=0,"",SUM(IF(OR(I7="",I$25=""),0,IF(I7=I$25,5,IFERROR(IF(SIGN(VALUE(LEFT(I7,FIND("x",I7)-1))-VALUE(MID(I7,FIND("x",I7)+1,99)))=SIGN(VALUE(LEFT(I$25,FIND("x",I$25)-1))-VALUE(MID(I$25,FIND("x",I$25)+1,99))),IF(VALUE(LEFT(I$25,FIND("x",I$25)-1))=VALUE(MID(I$25,FIND("x",I$25)+1,99)),1,2),0),0))),IF(OR(J7="",J$25=""),0,IF(J7=J$25,5,IFERROR(IF(SIGN(VALUE(LEFT(J7,FIND("x",J7)-1))-VALUE(MID(J7,FIND("x",J7)+1,99)))=SIGN(VALUE(LEFT(J$25,FIND("x",J$25)-1))-VALUE(MID(J$25,FIND("x",J$25)+1,99))),IF(VALUE(LEFT(J$25,FIND("x",J$25)-1))=VALUE(MID(J$25,FIND("x",J$25)+1,99)),1,2),0),0))))&" ("&SUM(IF(AND(I7<>"",I7=I$25),1,0),IF(AND(J7<>"",J7=J$25),1,0))&")") -> 2 (0) | M7: 16:00 Catar x Suíça | O7: Caio Borges | P7: 1x1 | Q7: 2x0 | R7: 1x2 | S7: 1x2 | T7: =IF(COUNTA(P7:S7)=0,"",SUM(IF(OR(P7="",P$25=""),0,IF(P7=P$25,5,IFERROR(IF(SIGN(VALUE(LEFT(P7,FIND("x",P7)-1))-VALUE(MID(P7,FIND("x",P7)+1,99)))=SIGN(VALUE(LEFT(P$25,FIND("x",P$25)-1))-VALUE(MID(P$25,FIND("x",P$25)+1,99))),IF(VALUE(LEFT(P$25,FIND("x",P$25)-1))=VALUE(MID(P$25,FIND("x",P$25)+1,99)),1,2),0),0))),IF(OR(Q7="",Q$25=""),0,IF(Q7=Q$25,5,IFERROR(IF(SIGN(VALUE(LEFT(Q7,FIND("x",Q7)-1))-VALUE(MID(Q7,FIND("x",Q7)+1,99)))=SIGN(VALUE(LEFT(Q$25,FIND("x",Q$25)-1))-VALUE(MID(Q$25,FIND("x",Q$25)+1,99))),IF(VALUE(LEFT(Q$25,FIND("x",Q$25)-1))=VALUE(MID(Q$25,FIND("x",Q$25)+1,99)),1,2),0),0))),IF(OR(R7="",R$25=""),0,IF(R7=R$25,5,IFERROR(IF(SIGN(VALUE(LEFT(R7,FIND("x",R7)-1))-VALUE(MID(R7,FIND("x",R7)+1,99)))=SIGN(VALUE(LEFT(R$25,FIND("x",R$25)-1))-VALUE(MID(R$25,FIND("x",R$25)+1,99))),IF(VALUE(LEFT(R$25,FIND("x",R$25)-1))=VALUE(MID(R$25,FIND("x",R$25)+1,99)),1,2),0),0))),IF(OR(S7="",S$25=""),0,IF(S7=S$25,5,IFERROR(IF(SIGN(VALUE(LEFT(S7,FIND("x",S7)-1))-VALUE(MID(S7,FIND("x",S7)+1,99)))=SIGN(VALUE(LEFT(S$25,FIND("x",S$25)-1))-VALUE(MID(S$25,FIND("x",S$25)+1,99))),IF(VALUE(LEFT(S$25,FIND("x",S$25)-1))=VALUE(MID(S$25,FIND("x",S$25)+1,99)),1,2),0),0))))&" ("&SUM(IF(AND(P7<>"",P7=P$25),1,0),IF(AND(Q7<>"",Q7=Q$25),1,0),IF(AND(R7<>"",R7=R$25),1,0),IF(AND(S7<>"",S7=S$25),1,0))&")") -> 7 (1) | V7: Caio Borges | AA7: =IF(COUNTA(W7:Z7)=0,"",SUM(IF(OR(W7="",W$25=""),0,IF(W7=W$25,5,IFERROR(IF(SIGN(VALUE(LEFT(W7,FIND("x",W7)-1))-VALUE(MID(W7,FIND("x",W7)+1,99)))=SIGN(VALUE(LEFT(W$25,FIND("x",W$25)-1))-VALUE(MID(W$25,FIND("x",W$25)+1,99))),IF(VALUE(LEFT(W$25,FIND("x",W$25)-1))=VALUE(MID(W$25,FIND("x",W$25)+1,99)),1,2),0),0))),IF(OR(X7="",X$25=""),0,IF(X7=X$25,5,IFERROR(IF(SIGN(VALUE(LEFT(X7,FIND("x",X7)-1))-VALUE(MID(X7,FIND("x",X7)+1,99)))=SIGN(VALUE(LEFT(X$25,FIND("x",X$25)-1))-VALUE(MID(X$25,FIND("x",X$25)+1,99))),IF(VALUE(LEFT(X$25,FIND("x",X$25)-1))=VALUE(MID(X$25,FIND("x",X$25)+1,99)),1,2),0),0))),IF(OR(Y7="",Y$25=""),0,IF(Y7=Y$25,5,IFERROR(IF(SIGN(VALUE(LEFT(Y7,FIND("x",Y7)-1))-VALUE(MID(Y7,FIND("x",Y7)+1,99)))=SIGN(VALUE(LEFT(Y$25,FIND("x",Y$25)-1))-VALUE(MID(Y$25,FIND("x",Y$25)+1,99))),IF(VALUE(LEFT(Y$25,FIND("x",Y$25)-1))=VALUE(MID(Y$25,FIND("x",Y$25)+1,99)),1,2),0),0))),IF(OR(Z7="",Z$25=""),0,IF(Z7=Z$25,5,IFERROR(IF(SIGN(VALUE(LEFT(Z7,FIND("x",Z7)-1))-VALUE(MID(Z7,FIND("x",Z7)+1,99)))=SIGN(VALUE(LEFT(Z$25,FIND("x",Z$25)-1))-VALUE(MID(Z$25,FIND("x",Z$25)+1,99))),IF(VALUE(LEFT(Z$25,FIND("x",Z$25)-1))=VALUE(MID(Z$25,FIND("x",Z$25)+1,99)),1,2),0),0))))&" ("&SUM(IF(AND(W7<>"",W7=W$25),1,0),IF(AND(X7<>"",X7=X$25),1,0),IF(AND(Y7<>"",Y7=Y$25),1,0),IF(AND(Z7<>"",Z7=Z$25),1,0))&")") | AC7: Karen | AH7: =IF(COUNTA(AD7:AG7)=0,"",SUM(IF(OR(AD7="",AD$14=""),0,IF(AD7=AD$14,5,IFERROR(IF(SIGN(VALUE(LEFT(AD7,FIND("x",AD7)-1))-VALUE(MID(AD7,FIND("x",AD7)+1,99)))=SIGN(VALUE(LEFT(AD$14,FIND("x",AD$14)-1))-VALUE(MID(AD$14,FIND("x",AD$14)+1,99))),IF(VALUE(LEFT(AD$14,FIND("x",AD$14)-1))=VALUE(MID(AD$14,FIND("x",AD$14)+1,99)),1,2),0),0))),IF(OR(AE7="",AE$14=""),0,IF(AE7=AE$14,5,IFERROR(IF(SIGN(VALUE(LEFT(AE7,FIND("x",AE7)-1))-VALUE(MID(AE7,FIND("x",AE7)+1,99)))=SIGN(VALUE(LEFT(AE$14,FIND("x",AE$14)-1))-VALUE(MID(AE$14,FIND("x",AE$14)+1,99))),IF(VALUE(LEFT(AE$14,FIND("x",AE$14)-1))=VALUE(MID(AE$14,FIND("x",AE$14)+1,99)),1,2),0),0))),IF(OR(AF7="",AF$14=""),0,IF(AF7=AF$14,5,IFERROR(IF(SIGN(VALUE(LEFT(AF7,FIND("x",AF7)-1))-VALUE(MID(AF7,FIND("x",AF7)+1,99)))=SIGN(VALUE(LEFT(AF$14,FIND("x",AF$14)-1))-VALUE(MID(AF$14,FIND("x",AF$14)+1,99))),IF(VALUE(LEFT(AF$14,FIND("x",AF$14)-1))=VALUE(MID(AF$14,FIND("x",AF$14)+1,99)),1,2),0),0))),IF(OR(AG7="",AG$14=""),0,IF(AG7=AG$14,5,IFERROR(IF(SIGN(VALUE(LEFT(AG7,FIND("x",AG7)-1))-VALUE(MID(AG7,FIND("x",AG7)+1,99)))=SIGN(VALUE(LEFT(AG$14,FIND("x",AG$14)-1))-VALUE(MID(AG$14,FIND("x",AG$14)+1,99))),IF(VALUE(LEFT(AG$14,FIND("x",AG$14)-1))=VALUE(MID(AG$14,FIND("x",AG$14)+1,99)),1,2),0),0))))&" ("&SUM(IF(AND(AD7<>"",AD7=AD$14),1,0),IF(AND(AE7<>"",AE7=AE$14),1,0),IF(AND(AF7<>"",AF7=AF$14),1,0),IF(AND(AG7<>"",AG7=AG$14),1,0))&")")
A8: Eduarda Peres | B8: 3x1 | C8: 2x1 | D8: =IF(COUNTA(B8:C8)=0,"",SUM(IF(OR(B8="",B$25=""),0,IF(B8=B$25,5,IFERROR(IF(SIGN(VALUE(LEFT(B8,FIND("x",B8)-1))-VALUE(MID(B8,FIND("x",B8)+1,99)))=SIGN(VALUE(LEFT(B$25,FIND("x",B$25)-1))-VALUE(MID(B$25,FIND("x",B$25)+1,99))),IF(VALUE(LEFT(B$25,FIND("x",B$25)-1))=VALUE(MID(B$25,FIND("x",B$25)+1,99)),1,2),0),0))),IF(OR(C8="",C$25=""),0,IF(C8=C$25,5,IFERROR(IF(SIGN(VALUE(LEFT(C8,FIND("x",C8)-1))-VALUE(MID(C8,FIND("x",C8)+1,99)))=SIGN(VALUE(LEFT(C$25,FIND("x",C$25)-1))-VALUE(MID(C$25,FIND("x",C$25)+1,99))),IF(VALUE(LEFT(C$25,FIND("x",C$25)-1))=VALUE(MID(C$25,FIND("x",C$25)+1,99)),1,2),0),0))))&" ("&SUM(IF(AND(B8<>"",B8=B$25),1,0),IF(AND(C8<>"",C8=C$25),1,0))&")") -> 7 (1) | H8: Eduarda Peres | I8: 2x0 | J8: 1x2 | K8: =IF(COUNTA(I8:J8)=0,"",SUM(IF(OR(I8="",I$25=""),0,IF(I8=I$25,5,IFERROR(IF(SIGN(VALUE(LEFT(I8,FIND("x",I8)-1))-VALUE(MID(I8,FIND("x",I8)+1,99)))=SIGN(VALUE(LEFT(I$25,FIND("x",I$25)-1))-VALUE(MID(I$25,FIND("x",I$25)+1,99))),IF(VALUE(LEFT(I$25,FIND("x",I$25)-1))=VALUE(MID(I$25,FIND("x",I$25)+1,99)),1,2),0),0))),IF(OR(J8="",J$25=""),0,IF(J8=J$25,5,IFERROR(IF(SIGN(VALUE(LEFT(J8,FIND("x",J8)-1))-VALUE(MID(J8,FIND("x",J8)+1,99)))=SIGN(VALUE(LEFT(J$25,FIND("x",J$25)-1))-VALUE(MID(J$25,FIND("x",J$25)+1,99))),IF(VALUE(LEFT(J$25,FIND("x",J$25)-1))=VALUE(MID(J$25,FIND("x",J$25)+1,99)),1,2),0),0))))&" ("&SUM(IF(AND(I8<>"",I8=I$25),1,0),IF(AND(J8<>"",J8=J$25),1,0))&")") -> 0 (0) | M8: 19:00 Brasil x Marrocos | O8: Eduarda Peres | P8: 1x3 | Q8: 3x1 | R8: 0x2 | S8: 3x1 | T8: =IF(COUNTA(P8:S8)=0,"",SUM(IF(OR(P8="",P$25=""),0,IF(P8=P$25,5,IFERROR(IF(SIGN(VALUE(LEFT(P8,FIND("x",P8)-1))-VALUE(MID(P8,FIND("x",P8)+1,99)))=SIGN(VALUE(LEFT(P$25,FIND("x",P$25)-1))-VALUE(MID(P$25,FIND("x",P$25)+1,99))),IF(VALUE(LEFT(P$25,FIND("x",P$25)-1))=VALUE(MID(P$25,FIND("x",P$25)+1,99)),1,2),0),0))),IF(OR(Q8="",Q$25=""),0,IF(Q8=Q$25,5,IFERROR(IF(SIGN(VALUE(LEFT(Q8,FIND("x",Q8)-1))-VALUE(MID(Q8,FIND("x",Q8)+1,99)))=SIGN(VALUE(LEFT(Q$25,FIND("x",Q$25)-1))-VALUE(MID(Q$25,FIND("x",Q$25)+1,99))),IF(VALUE(LEFT(Q$25,FIND("x",Q$25)-1))=VALUE(MID(Q$25,FIND("x",Q$25)+1,99)),1,2),0),0))),IF(OR(R8="",R$25=""),0,IF(R8=R$25,5,IFERROR(IF(SIGN(VALUE(LEFT(R8,FIND("x",R8)-1))-VALUE(MID(R8,FIND("x",R8)+1,99)))=SIGN(VALUE(LEFT(R$25,FIND("x",R$25)-1))-VALUE(MID(R$25,FIND("x",R$25)+1,99))),IF(VALUE(LEFT(R$25,FIND("x",R$25)-1))=VALUE(MID(R$25,FIND("x",R$25)+1,99)),1,2),0),0))),IF(OR(S8="",S$25=""),0,IF(S8=S$25,5,IFERROR(IF(SIGN(VALUE(LEFT(S8,FIND("x",S8)-1))-VALUE(MID(S8,FIND("x",S8)+1,99)))=SIGN(VALUE(LEFT(S$25,FIND("x",S$25)-1))-VALUE(MID(S$25,FIND("x",S$25)+1,99))),IF(VALUE(LEFT(S$25,FIND("x",S$25)-1))=VALUE(MID(S$25,FIND("x",S$25)+1,99)),1,2),0),0))))&" ("&SUM(IF(AND(P8<>"",P8=P$25),1,0),IF(AND(Q8<>"",Q8=Q$25),1,0),IF(AND(R8<>"",R8=R$25),1,0),IF(AND(S8<>"",S8=S$25),1,0))&")") -> 4 (0) | V8: Eduarda Peres | AA8: =IF(COUNTA(W8:Z8)=0,"",SUM(IF(OR(W8="",W$25=""),0,IF(W8=W$25,5,IFERROR(IF(SIGN(VALUE(LEFT(W8,FIND("x",W8)-1))-VALUE(MID(W8,FIND("x",W8)+1,99)))=SIGN(VALUE(LEFT(W$25,FIND("x",W$25)-1))-VALUE(MID(W$25,FIND("x",W$25)+1,99))),IF(VALUE(LEFT(W$25,FIND("x",W$25)-1))=VALUE(MID(W$25,FIND("x",W$25)+1,99)),1,2),0),0))),IF(OR(X8="",X$25=""),0,IF(X8=X$25,5,IFERROR(IF(SIGN(VALUE(LEFT(X8,FIND("x",X8)-1))-VALUE(MID(X8,FIND("x",X8)+1,99)))=SIGN(VALUE(LEFT(X$25,FIND("x",X$25)-1))-VALUE(MID(X$25,FIND("x",X$25)+1,99))),IF(VALUE(LEFT(X$25,FIND("x",X$25)-1))=VALUE(MID(X$25,FIND("x",X$25)+1,99)),1,2),0),0))),IF(OR(Y8="",Y$25=""),0,IF(Y8=Y$25,5,IFERROR(IF(SIGN(VALUE(LEFT(Y8,FIND("x",Y8)-1))-VALUE(MID(Y8,FIND("x",Y8)+1,99)))=SIGN(VALUE(LEFT(Y$25,FIND("x",Y$25)-1))-VALUE(MID(Y$25,FIND("x",Y$25)+1,99))),IF(VALUE(LEFT(Y$25,FIND("x",Y$25)-1))=VALUE(MID(Y$25,FIND("x",Y$25)+1,99)),1,2),0),0))),IF(OR(Z8="",Z$25=""),0,IF(Z8=Z$25,5,IFERROR(IF(SIGN(VALUE(LEFT(Z8,FIND("x",Z8)-1))-VALUE(MID(Z8,FIND("x",Z8)+1,99)))=SIGN(VALUE(LEFT(Z$25,FIND("x",Z$25)-1))-VALUE(MID(Z$25,FIND("x",Z$25)+1,99))),IF(VALUE(LEFT(Z$25,FIND("x",Z$25)-1))=VALUE(MID(Z$25,FIND("x",Z$25)+1,99)),1,2),0),0))))&" ("&SUM(IF(AND(W8<>"",W8=W$25),1,0),IF(AND(X8<>"",X8=X$25),1,0),IF(AND(Y8<>"",Y8=Y$25),1,0),IF(AND(Z8<>"",Z8=Z$25),1,0))&")") | AC8: Lucas | AH8: =IF(COUNTA(AD8:AG8)=0,"",SUM(IF(OR(AD8="",AD$14=""),0,IF(AD8=AD$14,5,IFERROR(IF(SIGN(VALUE(LEFT(AD8,FIND("x",AD8)-1))-VALUE(MID(AD8,FIND("x",AD8)+1,99)))=SIGN(VALUE(LEFT(AD$14,FIND("x",AD$14)-1))-VALUE(MID(AD$14,FIND("x",AD$14)+1,99))),IF(VALUE(LEFT(AD$14,FIND("x",AD$14)-1))=VALUE(MID(AD$14,FIND("x",AD$14)+1,99)),1,2),0),0))),IF(OR(AE8="",AE$14=""),0,IF(AE8=AE$14,5,IFERROR(IF(SIGN(VALUE(LEFT(AE8,FIND("x",AE8)-1))-VALUE(MID(AE8,FIND("x",AE8)+1,99)))=SIGN(VALUE(LEFT(AE$14,FIND("x",AE$14)-1))-VALUE(MID(AE$14,FIND("x",AE$14)+1,99))),IF(VALUE(LEFT(AE$14,FIND("x",AE$14)-1))=VALUE(MID(AE$14,FIND("x",AE$14)+1,99)),1,2),0),0))),IF(OR(AF8="",AF$14=""),0,IF(AF8=AF$14,5,IFERROR(IF(SIGN(VALUE(LEFT(AF8,FIND("x",AF8)-1))-VALUE(MID(AF8,FIND("x",AF8)+1,99)))=SIGN(VALUE(LEFT(AF$14,FIND("x",AF$14)-1))-VALUE(MID(AF$14,FIND("x",AF$14)+1,99))),IF(VALUE(LEFT(AF$14,FIND("x",AF$14)-1))=VALUE(MID(AF$14,FIND("x",AF$14)+1,99)),1,2),0),0))),IF(OR(AG8="",AG$14=""),0,IF(AG8=AG$14,5,IFERROR(IF(SIGN(VALUE(LEFT(AG8,FIND("x",AG8)-1))-VALUE(MID(AG8,FIND("x",AG8)+1,99)))=SIGN(VALUE(LEFT(AG$14,FIND("x",AG$14)-1))-VALUE(MID(AG$14,FIND("x",AG$14)+1,99))),IF(VALUE(LEFT(AG$14,FIND("x",AG$14)-1))=VALUE(MID(AG$14,FIND("x",AG$14)+1,99)),1,2),0),0))))&" ("&SUM(IF(AND(AD8<>"",AD8=AD$14),1,0),IF(AND(AE8<>"",AE8=AE$14),1,0),IF(AND(AF8<>"",AF8=AF$14),1,0),IF(AND(AG8<>"",AG8=AG$14),1,0))&")")
A9: Gabriel Mendes | B9: 2x1 | C9: 1x1 | D9: =IF(COUNTA(B9:C9)=0,"",SUM(IF(OR(B9="",B$25=""),0,IF(B9=B$25,5,IFERROR(IF(SIGN(VALUE(LEFT(B9,FIND("x",B9)-1))-VALUE(MID(B9,FIND("x",B9)+1,99)))=SIGN(VALUE(LEFT(B$25,FIND("x",B$25)-1))-VALUE(MID(B$25,FIND("x",B$25)+1,99))),IF(VALUE(LEFT(B$25,FIND("x",B$25)-1))=VALUE(MID(B$25,FIND("x",B$25)+1,99)),1,2),0),0))),IF(OR(C9="",C$25=""),0,IF(C9=C$25,5,IFERROR(IF(SIGN(VALUE(LEFT(C9,FIND("x",C9)-1))-VALUE(MID(C9,FIND("x",C9)+1,99)))=SIGN(VALUE(LEFT(C$25,FIND("x",C$25)-1))-VALUE(MID(C$25,FIND("x",C$25)+1,99))),IF(VALUE(LEFT(C$25,FIND("x",C$25)-1))=VALUE(MID(C$25,FIND("x",C$25)+1,99)),1,2),0),0))))&" ("&SUM(IF(AND(B9<>"",B9=B$25),1,0),IF(AND(C9<>"",C9=C$25),1,0))&")") -> 2 (0) | H9: Gabriel Mendes | I9: 1x1 | J9: 1x0 | K9: =IF(COUNTA(I9:J9)=0,"",SUM(IF(OR(I9="",I$25=""),0,IF(I9=I$25,5,IFERROR(IF(SIGN(VALUE(LEFT(I9,FIND("x",I9)-1))-VALUE(MID(I9,FIND("x",I9)+1,99)))=SIGN(VALUE(LEFT(I$25,FIND("x",I$25)-1))-VALUE(MID(I$25,FIND("x",I$25)+1,99))),IF(VALUE(LEFT(I$25,FIND("x",I$25)-1))=VALUE(MID(I$25,FIND("x",I$25)+1,99)),1,2),0),0))),IF(OR(J9="",J$25=""),0,IF(J9=J$25,5,IFERROR(IF(SIGN(VALUE(LEFT(J9,FIND("x",J9)-1))-VALUE(MID(J9,FIND("x",J9)+1,99)))=SIGN(VALUE(LEFT(J$25,FIND("x",J$25)-1))-VALUE(MID(J$25,FIND("x",J$25)+1,99))),IF(VALUE(LEFT(J$25,FIND("x",J$25)-1))=VALUE(MID(J$25,FIND("x",J$25)+1,99)),1,2),0),0))))&" ("&SUM(IF(AND(I9<>"",I9=I$25),1,0),IF(AND(J9<>"",J9=J$25),1,0))&")") -> 7 (1) | M9: 22:00 Haiti x Escócia | O9: Gabriel Mendes | P9: 0x2 | Q9: 1x1 | R9: 1x3 | S9: 0x2 | T9: =IF(COUNTA(P9:S9)=0,"",SUM(IF(OR(P9="",P$25=""),0,IF(P9=P$25,5,IFERROR(IF(SIGN(VALUE(LEFT(P9,FIND("x",P9)-1))-VALUE(MID(P9,FIND("x",P9)+1,99)))=SIGN(VALUE(LEFT(P$25,FIND("x",P$25)-1))-VALUE(MID(P$25,FIND("x",P$25)+1,99))),IF(VALUE(LEFT(P$25,FIND("x",P$25)-1))=VALUE(MID(P$25,FIND("x",P$25)+1,99)),1,2),0),0))),IF(OR(Q9="",Q$25=""),0,IF(Q9=Q$25,5,IFERROR(IF(SIGN(VALUE(LEFT(Q9,FIND("x",Q9)-1))-VALUE(MID(Q9,FIND("x",Q9)+1,99)))=SIGN(VALUE(LEFT(Q$25,FIND("x",Q$25)-1))-VALUE(MID(Q$25,FIND("x",Q$25)+1,99))),IF(VALUE(LEFT(Q$25,FIND("x",Q$25)-1))=VALUE(MID(Q$25,FIND("x",Q$25)+1,99)),1,2),0),0))),IF(OR(R9="",R$25=""),0,IF(R9=R$25,5,IFERROR(IF(SIGN(VALUE(LEFT(R9,FIND("x",R9)-1))-VALUE(MID(R9,FIND("x",R9)+1,99)))=SIGN(VALUE(LEFT(R$25,FIND("x",R$25)-1))-VALUE(MID(R$25,FIND("x",R$25)+1,99))),IF(VALUE(LEFT(R$25,FIND("x",R$25)-1))=VALUE(MID(R$25,FIND("x",R$25)+1,99)),1,2),0),0))),IF(OR(S9="",S$25=""),0,IF(S9=S$25,5,IFERROR(IF(SIGN(VALUE(LEFT(S9,FIND("x",S9)-1))-VALUE(MID(S9,FIND("x",S9)+1,99)))=SIGN(VALUE(LEFT(S$25,FIND("x",S$25)-1))-VALUE(MID(S$25,FIND("x",S$25)+1,99))),IF(VALUE(LEFT(S$25,FIND("x",S$25)-1))=VALUE(MID(S$25,FIND("x",S$25)+1,99)),1,2),0),0))))&" ("&SUM(IF(AND(P9<>"",P9=P$25),1,0),IF(AND(Q9<>"",Q9=Q$25),1,0),IF(AND(R9<>"",R9=R$25),1,0),IF(AND(S9<>"",S9=S$25),1,0))&")") -> 7 (1) | V9: Gabriel Mendes | AA9: =IF(COUNTA(W9:Z9)=0,"",SUM(IF(OR(W9="",W$25=""),0,IF(W9=W$25,5,IFERROR(IF(SIGN(VALUE(LEFT(W9,FIND("x",W9)-1))-VALUE(MID(W9,FIND("x",W9)+1,99)))=SIGN(VALUE(LEFT(W$25,FIND("x",W$25)-1))-VALUE(MID(W$25,FIND("x",W$25)+1,99))),IF(VALUE(LEFT(W$25,FIND("x",W$25)-1))=VALUE(MID(W$25,FIND("x",W$25)+1,99)),1,2),0),0))),IF(OR(X9="",X$25=""),0,IF(X9=X$25,5,IFERROR(IF(SIGN(VALUE(LEFT(X9,FIND("x",X9)-1))-VALUE(MID(X9,FIND("x",X9)+1,99)))=SIGN(VALUE(LEFT(X$25,FIND("x",X$25)-1))-VALUE(MID(X$25,FIND("x",X$25)+1,99))),IF(VALUE(LEFT(X$25,FIND("x",X$25)-1))=VALUE(MID(X$25,FIND("x",X$25)+1,99)),1,2),0),0))),IF(OR(Y9="",Y$25=""),0,IF(Y9=Y$25,5,IFERROR(IF(SIGN(VALUE(LEFT(Y9,FIND("x",Y9)-1))-VALUE(MID(Y9,FIND("x",Y9)+1,99)))=SIGN(VALUE(LEFT(Y$25,FIND("x",Y$25)-1))-VALUE(MID(Y$25,FIND("x",Y$25)+1,99))),IF(VALUE(LEFT(Y$25,FIND("x",Y$25)-1))=VALUE(MID(Y$25,FIND("x",Y$25)+1,99)),1,2),0),0))),IF(OR(Z9="",Z$25=""),0,IF(Z9=Z$25,5,IFERROR(IF(SIGN(VALUE(LEFT(Z9,FIND("x",Z9)-1))-VALUE(MID(Z9,FIND("x",Z9)+1,99)))=SIGN(VALUE(LEFT(Z$25,FIND("x",Z$25)-1))-VALUE(MID(Z$25,FIND("x",Z$25)+1,99))),IF(VALUE(LEFT(Z$25,FIND("x",Z$25)-1))=VALUE(MID(Z$25,FIND("x",Z$25)+1,99)),1,2),0),0))))&" ("&SUM(IF(AND(W9<>"",W9=W$25),1,0),IF(AND(X9<>"",X9=X$25),1,0),IF(AND(Y9<>"",Y9=Y$25),1,0),IF(AND(Z9<>"",Z9=Z$25),1,0))&")") | AC9: Maria Clara | AH9: =IF(COUNTA(AD9:AG9)=0,"",SUM(IF(OR(AD9="",AD$14=""),0,IF(AD9=AD$14,5,IFERROR(IF(SIGN(VALUE(LEFT(AD9,FIND("x",AD9)-1))-VALUE(MID(AD9,FIND("x",AD9)+1,99)))=SIGN(VALUE(LEFT(AD$14,FIND("x",AD$14)-1))-VALUE(MID(AD$14,FIND("x",AD$14)+1,99))),IF(VALUE(LEFT(AD$14,FIND("x",AD$14)-1))=VALUE(MID(AD$14,FIND("x",AD$14)+1,99)),1,2),0),0))),IF(OR(AE9="",AE$14=""),0,IF(AE9=AE$14,5,IFERROR(IF(SIGN(VALUE(LEFT(AE9,FIND("x",AE9)-1))-VALUE(MID(AE9,FIND("x",AE9)+1,99)))=SIGN(VALUE(LEFT(AE$14,FIND("x",AE$14)-1))-VALUE(MID(AE$14,FIND("x",AE$14)+1,99))),IF(VALUE(LEFT(AE$14,FIND("x",AE$14)-1))=VALUE(MID(AE$14,FIND("x",AE$14)+1,99)),1,2),0),0))),IF(OR(AF9="",AF$14=""),0,IF(AF9=AF$14,5,IFERROR(IF(SIGN(VALUE(LEFT(AF9,FIND("x",AF9)-1))-VALUE(MID(AF9,FIND("x",AF9)+1,99)))=SIGN(VALUE(LEFT(AF$14,FIND("x",AF$14)-1))-VALUE(MID(AF$14,FIND("x",AF$14)+1,99))),IF(VALUE(LEFT(AF$14,FIND("x",AF$14)-1))=VALUE(MID(AF$14,FIND("x",AF$14)+1,99)),1,2),0),0))),IF(OR(AG9="",AG$14=""),0,IF(AG9=AG$14,5,IFERROR(IF(SIGN(VALUE(LEFT(AG9,FIND("x",AG9)-1))-VALUE(MID(AG9,FIND("x",AG9)+1,99)))=SIGN(VALUE(LEFT(AG$14,FIND("x",AG$14)-1))-VALUE(MID(AG$14,FIND("x",AG$14)+1,99))),IF(VALUE(LEFT(AG$14,FIND("x",AG$14)-1))=VALUE(MID(AG$14,FIND("x",AG$14)+1,99)),1,2),0),0))))&" ("&SUM(IF(AND(AD9<>"",AD9=AD$14),1,0),IF(AND(AE9<>"",AE9=AE$14),1,0),IF(AND(AF9<>"",AF9=AF$14),1,0),IF(AND(AG9<>"",AG9=AG$14),1,0))&")")
A10: Guilherme Valadares | B10: 1x1 | C10: 0x1 | D10: =IF(COUNTA(B10:C10)=0,"",SUM(IF(OR(B10="",B$25=""),0,IF(B10=B$25,5,IFERROR(IF(SIGN(VALUE(LEFT(B10,FIND("x",B10)-1))-VALUE(MID(B10,FIND("x",B10)+1,99)))=SIGN(VALUE(LEFT(B$25,FIND("x",B$25)-1))-VALUE(MID(B$25,FIND("x",B$25)+1,99))),IF(VALUE(LEFT(B$25,FIND("x",B$25)-1))=VALUE(MID(B$25,FIND("x",B$25)+1,99)),1,2),0),0))),IF(OR(C10="",C$25=""),0,IF(C10=C$25,5,IFERROR(IF(SIGN(VALUE(LEFT(C10,FIND("x",C10)-1))-VALUE(MID(C10,FIND("x",C10)+1,99)))=SIGN(VALUE(LEFT(C$25,FIND("x",C$25)-1))-VALUE(MID(C$25,FIND("x",C$25)+1,99))),IF(VALUE(LEFT(C$25,FIND("x",C$25)-1))=VALUE(MID(C$25,FIND("x",C$25)+1,99)),1,2),0),0))))&" ("&SUM(IF(AND(B10<>"",B10=B$25),1,0),IF(AND(C10<>"",C10=C$25),1,0))&")") -> 0 (0) | H10: Guilherme Valadares | I10: 1x1 | J10: 1x2 | K10: =IF(COUNTA(I10:J10)=0,"",SUM(IF(OR(I10="",I$25=""),0,IF(I10=I$25,5,IFERROR(IF(SIGN(VALUE(LEFT(I10,FIND("x",I10)-1))-VALUE(MID(I10,FIND("x",I10)+1,99)))=SIGN(VALUE(LEFT(I$25,FIND("x",I$25)-1))-VALUE(MID(I$25,FIND("x",I$25)+1,99))),IF(VALUE(LEFT(I$25,FIND("x",I$25)-1))=VALUE(MID(I$25,FIND("x",I$25)+1,99)),1,2),0),0))),IF(OR(J10="",J$25=""),0,IF(J10=J$25,5,IFERROR(IF(SIGN(VALUE(LEFT(J10,FIND("x",J10)-1))-VALUE(MID(J10,FIND("x",J10)+1,99)))=SIGN(VALUE(LEFT(J$25,FIND("x",J$25)-1))-VALUE(MID(J$25,FIND("x",J$25)+1,99))),IF(VALUE(LEFT(J$25,FIND("x",J$25)-1))=VALUE(MID(J$25,FIND("x",J$25)+1,99)),1,2),0),0))))&" ("&SUM(IF(AND(I10<>"",I10=I$25),1,0),IF(AND(J10<>"",J10=J$25),1,0))&")") -> 5 (1) | M10: 01:00 Austrália x Turquia | O10: Guilherme Valadares | P10: 0x3 | Q10: 1x1 | R10: 0x4 | S10: 1x3 | T10: =IF(COUNTA(P10:S10)=0,"",SUM(IF(OR(P10="",P$25=""),0,IF(P10=P$25,5,IFERROR(IF(SIGN(VALUE(LEFT(P10,FIND("x",P10)-1))-VALUE(MID(P10,FIND("x",P10)+1,99)))=SIGN(VALUE(LEFT(P$25,FIND("x",P$25)-1))-VALUE(MID(P$25,FIND("x",P$25)+1,99))),IF(VALUE(LEFT(P$25,FIND("x",P$25)-1))=VALUE(MID(P$25,FIND("x",P$25)+1,99)),1,2),0),0))),IF(OR(Q10="",Q$25=""),0,IF(Q10=Q$25,5,IFERROR(IF(SIGN(VALUE(LEFT(Q10,FIND("x",Q10)-1))-VALUE(MID(Q10,FIND("x",Q10)+1,99)))=SIGN(VALUE(LEFT(Q$25,FIND("x",Q$25)-1))-VALUE(MID(Q$25,FIND("x",Q$25)+1,99))),IF(VALUE(LEFT(Q$25,FIND("x",Q$25)-1))=VALUE(MID(Q$25,FIND("x",Q$25)+1,99)),1,2),0),0))),IF(OR(R10="",R$25=""),0,IF(R10=R$25,5,IFERROR(IF(SIGN(VALUE(LEFT(R10,FIND("x",R10)-1))-VALUE(MID(R10,FIND("x",R10)+1,99)))=SIGN(VALUE(LEFT(R$25,FIND("x",R$25)-1))-VALUE(MID(R$25,FIND("x",R$25)+1,99))),IF(VALUE(LEFT(R$25,FIND("x",R$25)-1))=VALUE(MID(R$25,FIND("x",R$25)+1,99)),1,2),0),0))),IF(OR(S10="",S$25=""),0,IF(S10=S$25,5,IFERROR(IF(SIGN(VALUE(LEFT(S10,FIND("x",S10)-1))-VALUE(MID(S10,FIND("x",S10)+1,99)))=SIGN(VALUE(LEFT(S$25,FIND("x",S$25)-1))-VALUE(MID(S$25,FIND("x",S$25)+1,99))),IF(VALUE(LEFT(S$25,FIND("x",S$25)-1))=VALUE(MID(S$25,FIND("x",S$25)+1,99)),1,2),0),0))))&" ("&SUM(IF(AND(P10<>"",P10=P$25),1,0),IF(AND(Q10<>"",Q10=Q$25),1,0),IF(AND(R10<>"",R10=R$25),1,0),IF(AND(S10<>"",S10=S$25),1,0))&")") -> 7 (1) | V10: Guilherme Valadares | AA10: =IF(COUNTA(W10:Z10)=0,"",SUM(IF(OR(W10="",W$25=""),0,IF(W10=W$25,5,IFERROR(IF(SIGN(VALUE(LEFT(W10,FIND("x",W10)-1))-VALUE(MID(W10,FIND("x",W10)+1,99)))=SIGN(VALUE(LEFT(W$25,FIND("x",W$25)-1))-VALUE(MID(W$25,FIND("x",W$25)+1,99))),IF(VALUE(LEFT(W$25,FIND("x",W$25)-1))=VALUE(MID(W$25,FIND("x",W$25)+1,99)),1,2),0),0))),IF(OR(X10="",X$25=""),0,IF(X10=X$25,5,IFERROR(IF(SIGN(VALUE(LEFT(X10,FIND("x",X10)-1))-VALUE(MID(X10,FIND("x",X10)+1,99)))=SIGN(VALUE(LEFT(X$25,FIND("x",X$25)-1))-VALUE(MID(X$25,FIND("x",X$25)+1,99))),IF(VALUE(LEFT(X$25,FIND("x",X$25)-1))=VALUE(MID(X$25,FIND("x",X$25)+1,99)),1,2),0),0))),IF(OR(Y10="",Y$25=""),0,IF(Y10=Y$25,5,IFERROR(IF(SIGN(VALUE(LEFT(Y10,FIND("x",Y10)-1))-VALUE(MID(Y10,FIND("x",Y10)+1,99)))=SIGN(VALUE(LEFT(Y$25,FIND("x",Y$25)-1))-VALUE(MID(Y$25,FIND("x",Y$25)+1,99))),IF(VALUE(LEFT(Y$25,FIND("x",Y$25)-1))=VALUE(MID(Y$25,FIND("x",Y$25)+1,99)),1,2),0),0))),IF(OR(Z10="",Z$25=""),0,IF(Z10=Z$25,5,IFERROR(IF(SIGN(VALUE(LEFT(Z10,FIND("x",Z10)-1))-VALUE(MID(Z10,FIND("x",Z10)+1,99)))=SIGN(VALUE(LEFT(Z$25,FIND("x",Z$25)-1))-VALUE(MID(Z$25,FIND("x",Z$25)+1,99))),IF(VALUE(LEFT(Z$25,FIND("x",Z$25)-1))=VALUE(MID(Z$25,FIND("x",Z$25)+1,99)),1,2),0),0))))&" ("&SUM(IF(AND(W10<>"",W10=W$25),1,0),IF(AND(X10<>"",X10=X$25),1,0),IF(AND(Y10<>"",Y10=Y$25),1,0),IF(AND(Z10<>"",Z10=Z$25),1,0))&")") | AC10: Nicolas | AH10: =IF(COUNTA(AD10:AG10)=0,"",SUM(IF(OR(AD10="",AD$14=""),0,IF(AD10=AD$14,5,IFERROR(IF(SIGN(VALUE(LEFT(AD10,FIND("x",AD10)-1))-VALUE(MID(AD10,FIND("x",AD10)+1,99)))=SIGN(VALUE(LEFT(AD$14,FIND("x",AD$14)-1))-VALUE(MID(AD$14,FIND("x",AD$14)+1,99))),IF(VALUE(LEFT(AD$14,FIND("x",AD$14)-1))=VALUE(MID(AD$14,FIND("x",AD$14)+1,99)),1,2),0),0))),IF(OR(AE10="",AE$14=""),0,IF(AE10=AE$14,5,IFERROR(IF(SIGN(VALUE(LEFT(AE10,FIND("x",AE10)-1))-VALUE(MID(AE10,FIND("x",AE10)+1,99)))=SIGN(VALUE(LEFT(AE$14,FIND("x",AE$14)-1))-VALUE(MID(AE$14,FIND("x",AE$14)+1,99))),IF(VALUE(LEFT(AE$14,FIND("x",AE$14)-1))=VALUE(MID(AE$14,FIND("x",AE$14)+1,99)),1,2),0),0))),IF(OR(AF10="",AF$14=""),0,IF(AF10=AF$14,5,IFERROR(IF(SIGN(VALUE(LEFT(AF10,FIND("x",AF10)-1))-VALUE(MID(AF10,FIND("x",AF10)+1,99)))=SIGN(VALUE(LEFT(AF$14,FIND("x",AF$14)-1))-VALUE(MID(AF$14,FIND("x",AF$14)+1,99))),IF(VALUE(LEFT(AF$14,FIND("x",AF$14)-1))=VALUE(MID(AF$14,FIND("x",AF$14)+1,99)),1,2),0),0))),IF(OR(AG10="",AG$14=""),0,IF(AG10=AG$14,5,IFERROR(IF(SIGN(VALUE(LEFT(AG10,FIND("x",AG10)-1))-VALUE(MID(AG10,FIND("x",AG10)+1,99)))=SIGN(VALUE(LEFT(AG$14,FIND("x",AG$14)-1))-VALUE(MID(AG$14,FIND("x",AG$14)+1,99))),IF(VALUE(LEFT(AG$14,FIND("x",AG$14)-1))=VALUE(MID(AG$14,FIND("x",AG$14)+1,99)),1,2),0),0))))&" ("&SUM(IF(AND(AD10<>"",AD10=AD$14),1,0),IF(AND(AE10<>"",AE10=AE$14),1,0),IF(AND(AF10<>"",AF10=AF$14),1,0),IF(AND(AG10<>"",AG10=AG$14),1,0))&")")
A11: Karen Milene | B11: 3x1 | C11: 2x0 | D11: =IF(COUNTA(B11:C11)=0,"",SUM(IF(OR(B11="",B$25=""),0,IF(B11=B$25,5,IFERROR(IF(SIGN(VALUE(LEFT(B11,FIND("x",B11)-1))-VALUE(MID(B11,FIND("x",B11)+1,99)))=SIGN(VALUE(LEFT(B$25,FIND("x",B$25)-1))-VALUE(MID(B$25,FIND("x",B$25)+1,99))),IF(VALUE(LEFT(B$25,FIND("x",B$25)-1))=VALUE(MID(B$25,FIND("x",B$25)+1,99)),1,2),0),0))),IF(OR(C11="",C$25=""),0,IF(C11=C$25,5,IFERROR(IF(SIGN(VALUE(LEFT(C11,FIND("x",C11)-1))-VALUE(MID(C11,FIND("x",C11)+1,99)))=SIGN(VALUE(LEFT(C$25,FIND("x",C$25)-1))-VALUE(MID(C$25,FIND("x",C$25)+1,99))),IF(VALUE(LEFT(C$25,FIND("x",C$25)-1))=VALUE(MID(C$25,FIND("x",C$25)+1,99)),1,2),0),0))))&" ("&SUM(IF(AND(B11<>"",B11=B$25),1,0),IF(AND(C11<>"",C11=C$25),1,0))&")") -> 4 (0) | E11: Cravada = 5pts | H11: Karen Milene | I11: 2x1 | J11: 1x1 | K11: =IF(COUNTA(I11:J11)=0,"",SUM(IF(OR(I11="",I$25=""),0,IF(I11=I$25,5,IFERROR(IF(SIGN(VALUE(LEFT(I11,FIND("x",I11)-1))-VALUE(MID(I11,FIND("x",I11)+1,99)))=SIGN(VALUE(LEFT(I$25,FIND("x",I$25)-1))-VALUE(MID(I$25,FIND("x",I$25)+1,99))),IF(VALUE(LEFT(I$25,FIND("x",I$25)-1))=VALUE(MID(I$25,FIND("x",I$25)+1,99)),1,2),0),0))),IF(OR(J11="",J$25=""),0,IF(J11=J$25,5,IFERROR(IF(SIGN(VALUE(LEFT(J11,FIND("x",J11)-1))-VALUE(MID(J11,FIND("x",J11)+1,99)))=SIGN(VALUE(LEFT(J$25,FIND("x",J$25)-1))-VALUE(MID(J$25,FIND("x",J$25)+1,99))),IF(VALUE(LEFT(J$25,FIND("x",J$25)-1))=VALUE(MID(J$25,FIND("x",J$25)+1,99)),1,2),0),0))))&" ("&SUM(IF(AND(I11<>"",I11=I$25),1,0),IF(AND(J11<>"",J11=J$25),1,0))&")") -> 0 (0) | O11: Karen Milene | P11: 0x3 | Q11: 3x2 | R11: 1x3 | S11: 2x1 | T11: =IF(COUNTA(P11:S11)=0,"",SUM(IF(OR(P11="",P$25=""),0,IF(P11=P$25,5,IFERROR(IF(SIGN(VALUE(LEFT(P11,FIND("x",P11)-1))-VALUE(MID(P11,FIND("x",P11)+1,99)))=SIGN(VALUE(LEFT(P$25,FIND("x",P$25)-1))-VALUE(MID(P$25,FIND("x",P$25)+1,99))),IF(VALUE(LEFT(P$25,FIND("x",P$25)-1))=VALUE(MID(P$25,FIND("x",P$25)+1,99)),1,2),0),0))),IF(OR(Q11="",Q$25=""),0,IF(Q11=Q$25,5,IFERROR(IF(SIGN(VALUE(LEFT(Q11,FIND("x",Q11)-1))-VALUE(MID(Q11,FIND("x",Q11)+1,99)))=SIGN(VALUE(LEFT(Q$25,FIND("x",Q$25)-1))-VALUE(MID(Q$25,FIND("x",Q$25)+1,99))),IF(VALUE(LEFT(Q$25,FIND("x",Q$25)-1))=VALUE(MID(Q$25,FIND("x",Q$25)+1,99)),1,2),0),0))),IF(OR(R11="",R$25=""),0,IF(R11=R$25,5,IFERROR(IF(SIGN(VALUE(LEFT(R11,FIND("x",R11)-1))-VALUE(MID(R11,FIND("x",R11)+1,99)))=SIGN(VALUE(LEFT(R$25,FIND("x",R$25)-1))-VALUE(MID(R$25,FIND("x",R$25)+1,99))),IF(VALUE(LEFT(R$25,FIND("x",R$25)-1))=VALUE(MID(R$25,FIND("x",R$25)+1,99)),1,2),0),0))),IF(OR(S11="",S$25=""),0,IF(S11=S$25,5,IFERROR(IF(SIGN(VALUE(LEFT(S11,FIND("x",S11)-1))-VALUE(MID(S11,FIND("x",S11)+1,99)))=SIGN(VALUE(LEFT(S$25,FIND("x",S$25)-1))-VALUE(MID(S$25,FIND("x",S$25)+1,99))),IF(VALUE(LEFT(S$25,FIND("x",S$25)-1))=VALUE(MID(S$25,FIND("x",S$25)+1,99)),1,2),0),0))))&" ("&SUM(IF(AND(P11<>"",P11=P$25),1,0),IF(AND(Q11<>"",Q11=Q$25),1,0),IF(AND(R11<>"",R11=R$25),1,0),IF(AND(S11<>"",S11=S$25),1,0))&")") -> 4 (0) | V11: Karen Milene | AA11: =IF(COUNTA(W11:Z11)=0,"",SUM(IF(OR(W11="",W$25=""),0,IF(W11=W$25,5,IFERROR(IF(SIGN(VALUE(LEFT(W11,FIND("x",W11)-1))-VALUE(MID(W11,FIND("x",W11)+1,99)))=SIGN(VALUE(LEFT(W$25,FIND("x",W$25)-1))-VALUE(MID(W$25,FIND("x",W$25)+1,99))),IF(VALUE(LEFT(W$25,FIND("x",W$25)-1))=VALUE(MID(W$25,FIND("x",W$25)+1,99)),1,2),0),0))),IF(OR(X11="",X$25=""),0,IF(X11=X$25,5,IFERROR(IF(SIGN(VALUE(LEFT(X11,FIND("x",X11)-1))-VALUE(MID(X11,FIND("x",X11)+1,99)))=SIGN(VALUE(LEFT(X$25,FIND("x",X$25)-1))-VALUE(MID(X$25,FIND("x",X$25)+1,99))),IF(VALUE(LEFT(X$25,FIND("x",X$25)-1))=VALUE(MID(X$25,FIND("x",X$25)+1,99)),1,2),0),0))),IF(OR(Y11="",Y$25=""),0,IF(Y11=Y$25,5,IFERROR(IF(SIGN(VALUE(LEFT(Y11,FIND("x",Y11)-1))-VALUE(MID(Y11,FIND("x",Y11)+1,99)))=SIGN(VALUE(LEFT(Y$25,FIND("x",Y$25)-1))-VALUE(MID(Y$25,FIND("x",Y$25)+1,99))),IF(VALUE(LEFT(Y$25,FIND("x",Y$25)-1))=VALUE(MID(Y$25,FIND("x",Y$25)+1,99)),1,2),0),0))),IF(OR(Z11="",Z$25=""),0,IF(Z11=Z$25,5,IFERROR(IF(SIGN(VALUE(LEFT(Z11,FIND("x",Z11)-1))-VALUE(MID(Z11,FIND("x",Z11)+1,99)))=SIGN(VALUE(LEFT(Z$25,FIND("x",Z$25)-1))-VALUE(MID(Z$25,FIND("x",Z$25)+1,99))),IF(VALUE(LEFT(Z$25,FIND("x",Z$25)-1))=VALUE(MID(Z$25,FIND("x",Z$25)+1,99)),1,2),0),0))))&" ("&SUM(IF(AND(W11<>"",W11=W$25),1,0),IF(AND(X11<>"",X11=X$25),1,0),IF(AND(Y11<>"",Y11=Y$25),1,0),IF(AND(Z11<>"",Z11=Z$25),1,0))&")") | AC11: Victor | AH11: =IF(COUNTA(AD11:AG11)=0,"",SUM(IF(OR(AD11="",AD$14=""),0,IF(AD11=AD$14,5,IFERROR(IF(SIGN(VALUE(LEFT(AD11,FIND("x",AD11)-1))-VALUE(MID(AD11,FIND("x",AD11)+1,99)))=SIGN(VALUE(LEFT(AD$14,FIND("x",AD$14)-1))-VALUE(MID(AD$14,FIND("x",AD$14)+1,99))),IF(VALUE(LEFT(AD$14,FIND("x",AD$14)-1))=VALUE(MID(AD$14,FIND("x",AD$14)+1,99)),1,2),0),0))),IF(OR(AE11="",AE$14=""),0,IF(AE11=AE$14,5,IFERROR(IF(SIGN(VALUE(LEFT(AE11,FIND("x",AE11)-1))-VALUE(MID(AE11,FIND("x",AE11)+1,99)))=SIGN(VALUE(LEFT(AE$14,FIND("x",AE$14)-1))-VALUE(MID(AE$14,FIND("x",AE$14)+1,99))),IF(VALUE(LEFT(AE$14,FIND("x",AE$14)-1))=VALUE(MID(AE$14,FIND("x",AE$14)+1,99)),1,2),0),0))),IF(OR(AF11="",AF$14=""),0,IF(AF11=AF$14,5,IFERROR(IF(SIGN(VALUE(LEFT(AF11,FIND("x",AF11)-1))-VALUE(MID(AF11,FIND("x",AF11)+1,99)))=SIGN(VALUE(LEFT(AF$14,FIND("x",AF$14)-1))-VALUE(MID(AF$14,FIND("x",AF$14)+1,99))),IF(VALUE(LEFT(AF$14,FIND("x",AF$14)-1))=VALUE(MID(AF$14,FIND("x",AF$14)+1,99)),1,2),0),0))),IF(OR(AG11="",AG$14=""),0,IF(AG11=AG$14,5,IFERROR(IF(SIGN(VALUE(LEFT(AG11,FIND("x",AG11)-1))-VALUE(MID(AG11,FIND("x",AG11)+1,99)))=SIGN(VALUE(LEFT(AG$14,FIND("x",AG$14)-1))-VALUE(MID(AG$14,FIND("x",AG$14)+1,99))),IF(VALUE(LEFT(AG$14,FIND("x",AG$14)-1))=VALUE(MID(AG$14,FIND("x",AG$14)+1,99)),1,2),0),0))))&" ("&SUM(IF(AND(AD11<>"",AD11=AD$14),1,0),IF(AND(AE11<>"",AE11=AE$14),1,0),IF(AND(AF11<>"",AF11=AF$14),1,0),IF(AND(AG11<>"",AG11=AG$14),1,0))&")")
A12: Karolyne Azola | B12: 0x1 | C12: 2x1 | D12: =IF(COUNTA(B12:C12)=0,"",SUM(IF(OR(B12="",B$25=""),0,IF(B12=B$25,5,IFERROR(IF(SIGN(VALUE(LEFT(B12,FIND("x",B12)-1))-VALUE(MID(B12,FIND("x",B12)+1,99)))=SIGN(VALUE(LEFT(B$25,FIND("x",B$25)-1))-VALUE(MID(B$25,FIND("x",B$25)+1,99))),IF(VALUE(LEFT(B$25,FIND("x",B$25)-1))=VALUE(MID(B$25,FIND("x",B$25)+1,99)),1,2),0),0))),IF(OR(C12="",C$25=""),0,IF(C12=C$25,5,IFERROR(IF(SIGN(VALUE(LEFT(C12,FIND("x",C12)-1))-VALUE(MID(C12,FIND("x",C12)+1,99)))=SIGN(VALUE(LEFT(C$25,FIND("x",C$25)-1))-VALUE(MID(C$25,FIND("x",C$25)+1,99))),IF(VALUE(LEFT(C$25,FIND("x",C$25)-1))=VALUE(MID(C$25,FIND("x",C$25)+1,99)),1,2),0),0))))&" ("&SUM(IF(AND(B12<>"",B12=B$25),1,0),IF(AND(C12<>"",C12=C$25),1,0))&")") -> 5 (1) | E12: Placar/vencedor = 2pts | H12: Karolyne Azola | I12: 1x2 | J12: 1x1 | K12: =IF(COUNTA(I12:J12)=0,"",SUM(IF(OR(I12="",I$25=""),0,IF(I12=I$25,5,IFERROR(IF(SIGN(VALUE(LEFT(I12,FIND("x",I12)-1))-VALUE(MID(I12,FIND("x",I12)+1,99)))=SIGN(VALUE(LEFT(I$25,FIND("x",I$25)-1))-VALUE(MID(I$25,FIND("x",I$25)+1,99))),IF(VALUE(LEFT(I$25,FIND("x",I$25)-1))=VALUE(MID(I$25,FIND("x",I$25)+1,99)),1,2),0),0))),IF(OR(J12="",J$25=""),0,IF(J12=J$25,5,IFERROR(IF(SIGN(VALUE(LEFT(J12,FIND("x",J12)-1))-VALUE(MID(J12,FIND("x",J12)+1,99)))=SIGN(VALUE(LEFT(J$25,FIND("x",J$25)-1))-VALUE(MID(J$25,FIND("x",J$25)+1,99))),IF(VALUE(LEFT(J$25,FIND("x",J$25)-1))=VALUE(MID(J$25,FIND("x",J$25)+1,99)),1,2),0),0))))&" ("&SUM(IF(AND(I12<>"",I12=I$25),1,0),IF(AND(J12<>"",J12=J$25),1,0))&")") -> 0 (0) | O12: Karolyne Azola | P12: 1x3 | Q12: 2x1 | R12: 1x3 | S12: 1x1 | T12: =IF(COUNTA(P12:S12)=0,"",SUM(IF(OR(P12="",P$25=""),0,IF(P12=P$25,5,IFERROR(IF(SIGN(VALUE(LEFT(P12,FIND("x",P12)-1))-VALUE(MID(P12,FIND("x",P12)+1,99)))=SIGN(VALUE(LEFT(P$25,FIND("x",P$25)-1))-VALUE(MID(P$25,FIND("x",P$25)+1,99))),IF(VALUE(LEFT(P$25,FIND("x",P$25)-1))=VALUE(MID(P$25,FIND("x",P$25)+1,99)),1,2),0),0))),IF(OR(Q12="",Q$25=""),0,IF(Q12=Q$25,5,IFERROR(IF(SIGN(VALUE(LEFT(Q12,FIND("x",Q12)-1))-VALUE(MID(Q12,FIND("x",Q12)+1,99)))=SIGN(VALUE(LEFT(Q$25,FIND("x",Q$25)-1))-VALUE(MID(Q$25,FIND("x",Q$25)+1,99))),IF(VALUE(LEFT(Q$25,FIND("x",Q$25)-1))=VALUE(MID(Q$25,FIND("x",Q$25)+1,99)),1,2),0),0))),IF(OR(R12="",R$25=""),0,IF(R12=R$25,5,IFERROR(IF(SIGN(VALUE(LEFT(R12,FIND("x",R12)-1))-VALUE(MID(R12,FIND("x",R12)+1,99)))=SIGN(VALUE(LEFT(R$25,FIND("x",R$25)-1))-VALUE(MID(R$25,FIND("x",R$25)+1,99))),IF(VALUE(LEFT(R$25,FIND("x",R$25)-1))=VALUE(MID(R$25,FIND("x",R$25)+1,99)),1,2),0),0))),IF(OR(S12="",S$25=""),0,IF(S12=S$25,5,IFERROR(IF(SIGN(VALUE(LEFT(S12,FIND("x",S12)-1))-VALUE(MID(S12,FIND("x",S12)+1,99)))=SIGN(VALUE(LEFT(S$25,FIND("x",S$25)-1))-VALUE(MID(S$25,FIND("x",S$25)+1,99))),IF(VALUE(LEFT(S$25,FIND("x",S$25)-1))=VALUE(MID(S$25,FIND("x",S$25)+1,99)),1,2),0),0))))&" ("&SUM(IF(AND(P12<>"",P12=P$25),1,0),IF(AND(Q12<>"",Q12=Q$25),1,0),IF(AND(R12<>"",R12=R$25),1,0),IF(AND(S12<>"",S12=S$25),1,0))&")") -> 2 (0) | V12: Karolyne Azola | AA12: =IF(COUNTA(W12:Z12)=0,"",SUM(IF(OR(W12="",W$25=""),0,IF(W12=W$25,5,IFERROR(IF(SIGN(VALUE(LEFT(W12,FIND("x",W12)-1))-VALUE(MID(W12,FIND("x",W12)+1,99)))=SIGN(VALUE(LEFT(W$25,FIND("x",W$25)-1))-VALUE(MID(W$25,FIND("x",W$25)+1,99))),IF(VALUE(LEFT(W$25,FIND("x",W$25)-1))=VALUE(MID(W$25,FIND("x",W$25)+1,99)),1,2),0),0))),IF(OR(X12="",X$25=""),0,IF(X12=X$25,5,IFERROR(IF(SIGN(VALUE(LEFT(X12,FIND("x",X12)-1))-VALUE(MID(X12,FIND("x",X12)+1,99)))=SIGN(VALUE(LEFT(X$25,FIND("x",X$25)-1))-VALUE(MID(X$25,FIND("x",X$25)+1,99))),IF(VALUE(LEFT(X$25,FIND("x",X$25)-1))=VALUE(MID(X$25,FIND("x",X$25)+1,99)),1,2),0),0))),IF(OR(Y12="",Y$25=""),0,IF(Y12=Y$25,5,IFERROR(IF(SIGN(VALUE(LEFT(Y12,FIND("x",Y12)-1))-VALUE(MID(Y12,FIND("x",Y12)+1,99)))=SIGN(VALUE(LEFT(Y$25,FIND("x",Y$25)-1))-VALUE(MID(Y$25,FIND("x",Y$25)+1,99))),IF(VALUE(LEFT(Y$25,FIND("x",Y$25)-1))=VALUE(MID(Y$25,FIND("x",Y$25)+1,99)),1,2),0),0))),IF(OR(Z12="",Z$25=""),0,IF(Z12=Z$25,5,IFERROR(IF(SIGN(VALUE(LEFT(Z12,FIND("x",Z12)-1))-VALUE(MID(Z12,FIND("x",Z12)+1,99)))=SIGN(VALUE(LEFT(Z$25,FIND("x",Z$25)-1))-VALUE(MID(Z$25,FIND("x",Z$25)+1,99))),IF(VALUE(LEFT(Z$25,FIND("x",Z$25)-1))=VALUE(MID(Z$25,FIND("x",Z$25)+1,99)),1,2),0),0))))&" ("&SUM(IF(AND(W12<>"",W12=W$25),1,0),IF(AND(X12<>"",X12=X$25),1,0),IF(AND(Y12<>"",Y12=Y$25),1,0),IF(AND(Z12<>"",Z12=Z$25),1,0))&")") | AC12: Vinicius | AH12: =IF(COUNTA(AD12:AG12)=0,"",SUM(IF(OR(AD12="",AD$14=""),0,IF(AD12=AD$14,5,IFERROR(IF(SIGN(VALUE(LEFT(AD12,FIND("x",AD12)-1))-VALUE(MID(AD12,FIND("x",AD12)+1,99)))=SIGN(VALUE(LEFT(AD$14,FIND("x",AD$14)-1))-VALUE(MID(AD$14,FIND("x",AD$14)+1,99))),IF(VALUE(LEFT(AD$14,FIND("x",AD$14)-1))=VALUE(MID(AD$14,FIND("x",AD$14)+1,99)),1,2),0),0))),IF(OR(AE12="",AE$14=""),0,IF(AE12=AE$14,5,IFERROR(IF(SIGN(VALUE(LEFT(AE12,FIND("x",AE12)-1))-VALUE(MID(AE12,FIND("x",AE12)+1,99)))=SIGN(VALUE(LEFT(AE$14,FIND("x",AE$14)-1))-VALUE(MID(AE$14,FIND("x",AE$14)+1,99))),IF(VALUE(LEFT(AE$14,FIND("x",AE$14)-1))=VALUE(MID(AE$14,FIND("x",AE$14)+1,99)),1,2),0),0))),IF(OR(AF12="",AF$14=""),0,IF(AF12=AF$14,5,IFERROR(IF(SIGN(VALUE(LEFT(AF12,FIND("x",AF12)-1))-VALUE(MID(AF12,FIND("x",AF12)+1,99)))=SIGN(VALUE(LEFT(AF$14,FIND("x",AF$14)-1))-VALUE(MID(AF$14,FIND("x",AF$14)+1,99))),IF(VALUE(LEFT(AF$14,FIND("x",AF$14)-1))=VALUE(MID(AF$14,FIND("x",AF$14)+1,99)),1,2),0),0))),IF(OR(AG12="",AG$14=""),0,IF(AG12=AG$14,5,IFERROR(IF(SIGN(VALUE(LEFT(AG12,FIND("x",AG12)-1))-VALUE(MID(AG12,FIND("x",AG12)+1,99)))=SIGN(VALUE(LEFT(AG$14,FIND("x",AG$14)-1))-VALUE(MID(AG$14,FIND("x",AG$14)+1,99))),IF(VALUE(LEFT(AG$14,FIND("x",AG$14)-1))=VALUE(MID(AG$14,FIND("x",AG$14)+1,99)),1,2),0),0))))&" ("&SUM(IF(AND(AD12<>"",AD12=AD$14),1,0),IF(AND(AE12<>"",AE12=AE$14),1,0),IF(AND(AF12<>"",AF12=AF$14),1,0),IF(AND(AG12<>"",AG12=AG$14),1,0))&")")
